Workbook

Sheet CHECK_FORMULAS_EVENT_88
A1: BẢNG KIỂM TRA HÀM CÔNG THỨC EXCEL - EVENT 8.8 (NTB)
A2: File đối chiếu công thức Excel từ sheet 6_FC_Lay_Daily, 7_FC_Giao_Daily & FC Sorting 60d
A4: 1. VOLUME LẤY THEO SÀN (Event 8.8)
A5: Sàn / Kênh | B5: 06/08 | C5: 07/08 | D5: 08/08 | E5: 09/08 | F5: 10/08 | G5: 11/08 | H5: 12/08 | I5: 13/08 | J5: 14/08 | K5: 15/08 | L5: Tổng 10 ngày | M5: Trung bình
A6: Shopee | B6: =SUMIFS('6_FC_Lay_Daily'!AB:AB, '6_FC_Lay_Daily'!$E:$E, $A6) | C6: =SUMIFS('6_FC_Lay_Daily'!AC:AC, '6_FC_Lay_Daily'!$E:$E, $A6) | D6: =SUMIFS('6_FC_Lay_Daily'!AD:AD, '6_FC_Lay_Daily'!$E:$E, $A6) | E6: =SUMIFS('6_FC_Lay_Daily'!AE:AE, '6_FC_Lay_Daily'!$E:$E, $A6) | F6: =SUMIFS('6_FC_Lay_Daily'!AF:AF, '6_FC_Lay_Daily'!$E:$E, $A6) | G6: =SUMIFS('6_FC_Lay_Daily'!AG:AG, '6_FC_Lay_Daily'!$E:$E, $A6) | H6: =SUMIFS('6_FC_Lay_Daily'!AH:AH, '6_FC_Lay_Daily'!$E:$E, $A6) | I6: =SUMIFS('6_FC_Lay_Daily'!AI:AI, '6_FC_Lay_Daily'!$E:$E, $A6) | J6: =SUMIFS('6_FC_Lay_Daily'!AJ:AJ, '6_FC_Lay_Daily'!$E:$E, $A6) | K6: =SUMIFS('6_FC_Lay_Daily'!AK:AK, '6_FC_Lay_Daily'!$E:$E, $A6) | L6: =SUM(B6:K6) | M6: =AVERAGE(B6:K6)
A7: Shopee-Bulky | B7: =SUMIFS('6_FC_Lay_Daily'!AB:AB, '6_FC_Lay_Daily'!$E:$E, $A7) | C7: =SUMIFS('6_FC_Lay_Daily'!AC:AC, '6_FC_Lay_Daily'!$E:$E, $A7) | D7: =SUMIFS('6_FC_Lay_Daily'!AD:AD, '6_FC_Lay_Daily'!$E:$E, $A7) | E7: =SUMIFS('6_FC_Lay_Daily'!AE:AE, '6_FC_Lay_Daily'!$E:$E, $A7) | F7: =SUMIFS('6_FC_Lay_Daily'!AF:AF, '6_FC_Lay_Daily'!$E:$E, $A7) | G7: =SUMIFS('6_FC_Lay_Daily'!AG:AG, '6_FC_Lay_Daily'!$E:$E, $A7) | H7: =SUMIFS('6_FC_Lay_Daily'!AH:AH, '6_FC_Lay_Daily'!$E:$E, $A7) | I7: =SUMIFS('6_FC_Lay_Daily'!AI:AI, '6_FC_Lay_Daily'!$E:$E, $A7) | J7: =SUMIFS('6_FC_Lay_Daily'!AJ:AJ, '6_FC_Lay_Daily'!$E:$E, $A7) | K7: =SUMIFS('6_FC_Lay_Daily'!AK:AK, '6_FC_Lay_Daily'!$E:$E, $A7) | L7: =SUM(B7:K7) | M7: =AVERAGE(B7:K7)
A8: Shopee-Bulky (10-15kg) | B8: =SUMIFS('6_FC_Lay_Daily'!AB:AB, '6_FC_Lay_Daily'!$E:$E, $A8) | C8: =SUMIFS('6_FC_Lay_Daily'!AC:AC, '6_FC_Lay_Daily'!$E:$E, $A8) | D8: =SUMIFS('6_FC_Lay_Daily'!AD:AD, '6_FC_Lay_Daily'!$E:$E, $A8) | E8: =SUMIFS('6_FC_Lay_Daily'!AE:AE, '6_FC_Lay_Daily'!$E:$E, $A8) | F8: =SUMIFS('6_FC_Lay_Daily'!AF:AF, '6_FC_Lay_Daily'!$E:$E, $A8) | G8: =SUMIFS('6_FC_Lay_Daily'!AG:AG, '6_FC_Lay_Daily'!$E:$E, $A8) | H8: =SUMIFS('6_FC_Lay_Daily'!AH:AH, '6_FC_Lay_Daily'!$E:$E, $A8) | I8: =SUMIFS('6_FC_Lay_Daily'!AI:AI, '6_FC_Lay_Daily'!$E:$E, $A8) | J8: =SUMIFS('6_FC_Lay_Daily'!AJ:AJ, '6_FC_Lay_Daily'!$E:$E, $A8) | K8: =SUMIFS('6_FC_Lay_Daily'!AK:AK, '6_FC_Lay_Daily'!$E:$E, $A8) | L8: =SUM(B8:K8) | M8: =AVERAGE(B8:K8)
A9: SME | B9: =SUMIFS('6_FC_Lay_Daily'!AB:AB, '6_FC_Lay_Daily'!$E:$E, $A9) | C9: =SUMIFS('6_FC_Lay_Daily'!AC:AC, '6_FC_Lay_Daily'!$E:$E, $A9) | D9: =SUMIFS('6_FC_Lay_Daily'!AD:AD, '6_FC_Lay_Daily'!$E:$E, $A9) | E9: =SUMIFS('6_FC_Lay_Daily'!AE:AE, '6_FC_Lay_Daily'!$E:$E, $A9) | F9: =SUMIFS('6_FC_Lay_Daily'!AF:AF, '6_FC_Lay_Daily'!$E:$E, $A9) | G9: =SUMIFS('6_FC_Lay_Daily'!AG:AG, '6_FC_Lay_Daily'!$E:$E, $A9) | H9: =SUMIFS('6_FC_Lay_Daily'!AH:AH, '6_FC_Lay_Daily'!$E:$E, $A9) | I9: =SUMIFS('6_FC_Lay_Daily'!AI:AI, '6_FC_Lay_Daily'!$E:$E, $A9) | J9: =SUMIFS('6_FC_Lay_Daily'!AJ:AJ, '6_FC_Lay_Daily'!$E:$E, $A9) | K9: =SUMIFS('6_FC_Lay_Daily'!AK:AK, '6_FC_Lay_Daily'!$E:$E, $A9) | L9: =SUM(B9:K9) | M9: =AVERAGE(B9:K9)
A10: SME-Bulky | B10: =SUMIFS('6_FC_Lay_Daily'!AB:AB, '6_FC_Lay_Daily'!$E:$E, $A10) | C10: =SUMIFS('6_FC_Lay_Daily'!AC:AC, '6_FC_Lay_Daily'!$E:$E, $A10) | D10: =SUMIFS('6_FC_Lay_Daily'!AD:AD, '6_FC_Lay_Daily'!$E:$E, $A10) | E10: =SUMIFS('6_FC_Lay_Daily'!AE:AE, '6_FC_Lay_Daily'!$E:$E, $A10) | F10: =SUMIFS('6_FC_Lay_Daily'!AF:AF, '6_FC_Lay_Daily'!$E:$E, $A10) | G10: =SUMIFS('6_FC_Lay_Daily'!AG:AG, '6_FC_Lay_Daily'!$E:$E, $A10) | H10: =SUMIFS('6_FC_Lay_Daily'!AH:AH, '6_FC_Lay_Daily'!$E:$E, $A10) | I10: =SUMIFS('6_FC_Lay_Daily'!AI:AI, '6_FC_Lay_Daily'!$E:$E, $A10) | J10: =SUMIFS('6_FC_Lay_Daily'!AJ:AJ, '6_FC_Lay_Daily'!$E:$E, $A10) | K10: =SUMIFS('6_FC_Lay_Daily'!AK:AK, '6_FC_Lay_Daily'!$E:$E, $A10) | L10: =SUM(B10:K10) | M10: =AVERAGE(B10:K10)
A11: TTS | B11: =SUMIFS('6_FC_Lay_Daily'!AB:AB, '6_FC_Lay_Daily'!$E:$E, $A11) | C11: =SUMIFS('6_FC_Lay_Daily'!AC:AC, '6_FC_Lay_Daily'!$E:$E, $A11) | D11: =SUMIFS('6_FC_Lay_Daily'!AD:AD, '6_FC_Lay_Daily'!$E:$E, $A11) | E11: =SUMIFS('6_FC_Lay_Daily'!AE:AE, '6_FC_Lay_Daily'!$E:$E, $A11) | F11: =SUMIFS('6_FC_Lay_Daily'!AF:AF, '6_FC_Lay_Daily'!$E:$E, $A11) | G11: =SUMIFS('6_FC_Lay_Daily'!AG:AG, '6_FC_Lay_Daily'!$E:$E, $A11) | H11: =SUMIFS('6_FC_Lay_Daily'!AH:AH, '6_FC_Lay_Daily'!$E:$E, $A11) | I11: =SUMIFS('6_FC_Lay_Daily'!AI:AI, '6_FC_Lay_Daily'!$E:$E, $A11) | J11: =SUMIFS('6_FC_Lay_Daily'!AJ:AJ, '6_FC_Lay_Daily'!$E:$E, $A11) | K11: =SUMIFS('6_FC_Lay_Daily'!AK:AK, '6_FC_Lay_Daily'!$E:$E, $A11) | L11: =SUM(B11:K11) | M11: =AVERAGE(B11:K11)
A12: TTS-Bulky | B12: =SUMIFS('6_FC_Lay_Daily'!AB:AB, '6_FC_Lay_Daily'!$E:$E, $A12) | C12: =SUMIFS('6_FC_Lay_Daily'!AC:AC, '6_FC_Lay_Daily'!$E:$E, $A12) | D12: =SUMIFS('6_FC_Lay_Daily'!AD:AD, '6_FC_Lay_Daily'!$E:$E, $A12) | E12: =SUMIFS('6_FC_Lay_Daily'!AE:AE, '6_FC_Lay_Daily'!$E:$E, $A12) | F12: =SUMIFS('6_FC_Lay_Daily'!AF:AF, '6_FC_Lay_Daily'!$E:$E, $A12) | G12: =SUMIFS('6_FC_Lay_Daily'!AG:AG, '6_FC_Lay_Daily'!$E:$E, $A12) | H12: =SUMIFS('6_FC_Lay_Daily'!AH:AH, '6_FC_Lay_Daily'!$E:$E, $A12) | I12: =SUMIFS('6_FC_Lay_Daily'!AI:AI, '6_FC_Lay_Daily'!$E:$E, $A12) | J12: =SUMIFS('6_FC_Lay_Daily'!AJ:AJ, '6_FC_Lay_Daily'!$E:$E, $A12) | K12: =SUMIFS('6_FC_Lay_Daily'!AK:AK, '6_FC_Lay_Daily'!$E:$E, $A12) | L12: =SUM(B12:K12) | M12: =AVERAGE(B12:K12)
A13: Grand Total | B13: =SUM(B6:B12) | C13: =SUM(C6:C12) | D13: =SUM(D6:D12) | E13: =SUM(E6:E12) | F13: =SUM(F6:F12) | G13: =SUM(G6:G12) | H13: =SUM(H6:H12) | I13: =SUM(I6:I12) | ... M13: =SUM(M6:M12)
A16: 2. VOLUME LẤY THEO TỈNH/QUẬN (Event 8.8)
A17: Tỉnh / Quận | B17: 06/08 | C17: 07/08 | D17: 08/08 | E17: 09/08 | F17: 10/08 | G17: 11/08 | H17: 12/08 | I17: 13/08 | J17: 14/08 | K17: 15/08 | L17: Tổng 10 ngày | M17: Trung bình
A18: Bình Thuận | B18: =SUMIFS('6_FC_Lay_Daily'!AB:AB, '6_FC_Lay_Daily'!$B:$B, $A18) | C18: =SUMIFS('6_FC_Lay_Daily'!AC:AC, '6_FC_Lay_Daily'!$B:$B, $A18) | D18: =SUMIFS('6_FC_Lay_Daily'!AD:AD, '6_FC_Lay_Daily'!$B:$B, $A18) | E18: =SUMIFS('6_FC_Lay_Daily'!AE:AE, '6_FC_Lay_Daily'!$B:$B, $A18) | F18: =SUMIFS('6_FC_Lay_Daily'!AF:AF, '6_FC_Lay_Daily'!$B:$B, $A18) | G18: =SUMIFS('6_FC_Lay_Daily'!AG:AG, '6_FC_Lay_Daily'!$B:$B, $A18) | H18: =SUMIFS('6_FC_Lay_Daily'!AH:AH, '6_FC_Lay_Daily'!$B:$B, $A18) | I18: =SUMIFS('6_FC_Lay_Daily'!AI:AI, '6_FC_Lay_Daily'!$B:$B, $A18) | J18: =SUMIFS('6_FC_Lay_Daily'!AJ:AJ, '6_FC_Lay_Daily'!$B:$B, $A18) | K18: =SUMIFS('6_FC_Lay_Daily'!AK:AK, '6_FC_Lay_Daily'!$B:$B, $A18) | L18: =SUM(B18:K18) | M18: =AVERAGE(B18:K18)
A19: Khánh Hòa | B19: =SUMIFS('6_FC_Lay_Daily'!AB:AB, '6_FC_Lay_Daily'!$B:$B, $A19) | C19: =SUMIFS('6_FC_Lay_Daily'!AC:AC, '6_FC_Lay_Daily'!$B:$B, $A19) | D19: =SUMIFS('6_FC_Lay_Daily'!AD:AD, '6_FC_Lay_Daily'!$B:$B, $A19) | E19: =SUMIFS('6_FC_Lay_Daily'!AE:AE, '6_FC_Lay_Daily'!$B:$B, $A19) | F19: =SUMIFS('6_FC_Lay_Daily'!AF:AF, '6_FC_Lay_Daily'!$B:$B, $A19) | G19: =SUMIFS('6_FC_Lay_Daily'!AG:AG, '6_FC_Lay_Daily'!$B:$B, $A19) | H19: =SUMIFS('6_FC_Lay_Daily'!AH:AH, '6_FC_Lay_Daily'!$B:$B, $A19) | I19: =SUMIFS('6_FC_Lay_Daily'!AI:AI, '6_FC_Lay_Daily'!$B:$B, $A19) | J19: =SUMIFS('6_FC_Lay_Daily'!AJ:AJ, '6_FC_Lay_Daily'!$B:$B, $A19) | K19: =SUMIFS('6_FC_Lay_Daily'!AK:AK, '6_FC_Lay_Daily'!$B:$B, $A19) | L19: =SUM(B19:K19) | M19: =AVERAGE(B19:K19)
A20: Lâm Đồng | B20: =SUMIFS('6_FC_Lay_Daily'!AB:AB, '6_FC_Lay_Daily'!$B:$B, $A20) | C20: =SUMIFS('6_FC_Lay_Daily'!AC:AC, '6_FC_Lay_Daily'!$B:$B, $A20) | D20: =SUMIFS('6_FC_Lay_Daily'!AD:AD, '6_FC_Lay_Daily'!$B:$B, $A20) | E20: =SUMIFS('6_FC_Lay_Daily'!AE:AE, '6_FC_Lay_Daily'!$B:$B, $A20) | F20: =SUMIFS('6_FC_Lay_Daily'!AF:AF, '6_FC_Lay_Daily'!$B:$B, $A20) | G20: =SUMIFS('6_FC_Lay_Daily'!AG:AG, '6_FC_Lay_Daily'!$B:$B, $A20) | H20: =SUMIFS('6_FC_Lay_Daily'!AH:AH, '6_FC_Lay_Daily'!$B:$B, $A20) | I20: =SUMIFS('6_FC_Lay_Daily'!AI:AI, '6_FC_Lay_Daily'!$B:$B, $A20) | J20: =SUMIFS('6_FC_Lay_Daily'!AJ:AJ, '6_FC_Lay_Daily'!$B:$B, $A20) | K20: =SUMIFS('6_FC_Lay_Daily'!AK:AK, '6_FC_Lay_Daily'!$B:$B, $A20) | L20: =SUM(B20:K20) | M20: =AVERAGE(B20:K20)
A21: Ninh Thuận | B21: =SUMIFS('6_FC_Lay_Daily'!AB:AB, '6_FC_Lay_Daily'!$B:$B, $A21) | C21: =SUMIFS('6_FC_Lay_Daily'!AC:AC, '6_FC_Lay_Daily'!$B:$B, $A21) | D21: =SUMIFS('6_FC_Lay_Daily'!AD:AD, '6_FC_Lay_Daily'!$B:$B, $A21) | E21: =SUMIFS('6_FC_Lay_Daily'!AE:AE, '6_FC_Lay_Daily'!$B:$B, $A21) | F21: =SUMIFS('6_FC_Lay_Daily'!AF:AF, '6_FC_Lay_Daily'!$B:$B, $A21) | G21: =SUMIFS('6_FC_Lay_Daily'!AG:AG, '6_FC_Lay_Daily'!$B:$B, $A21) | H21: =SUMIFS('6_FC_Lay_Daily'!AH:AH, '6_FC_Lay_Daily'!$B:$B, $A21) | I21: =SUMIFS('6_FC_Lay_Daily'!AI:AI, '6_FC_Lay_Daily'!$B:$B, $A21) | J21: =SUMIFS('6_FC_Lay_Daily'!AJ:AJ, '6_FC_Lay_Daily'!$B:$B, $A21) | K21: =SUMIFS('6_FC_Lay_Daily'!AK:AK, '6_FC_Lay_Daily'!$B:$B, $A21) | L21: =SUM(B21:K21) | M21: =AVERAGE(B21:K21)
A22: Đắk Nông | B22: =SUMIFS('6_FC_Lay_Daily'!AB:AB, '6_FC_Lay_Daily'!$B:$B, $A22) | C22: =SUMIFS('6_FC_Lay_Daily'!AC:AC, '6_FC_Lay_Daily'!$B:$B, $A22) | D22: =SUMIFS('6_FC_Lay_Daily'!AD:AD, '6_FC_Lay_Daily'!$B:$B, $A22) | E22: =SUMIFS('6_FC_Lay_Daily'!AE:AE, '6_FC_Lay_Daily'!$B:$B, $A22) | F22: =SUMIFS('6_FC_Lay_Daily'!AF:AF, '6_FC_Lay_Daily'!$B:$B, $A22) | G22: =SUMIFS('6_FC_Lay_Daily'!AG:AG, '6_FC_Lay_Daily'!$B:$B, $A22) | H22: =SUMIFS('6_FC_Lay_Daily'!AH:AH, '6_FC_Lay_Daily'!$B:$B, $A22) | I22: =SUMIFS('6_FC_Lay_Daily'!AI:AI, '6_FC_Lay_Daily'!$B:$B, $A22) | J22: =SUMIFS('6_FC_Lay_Daily'!AJ:AJ, '6_FC_Lay_Daily'!$B:$B, $A22) | K22: =SUMIFS('6_FC_Lay_Daily'!AK:AK, '6_FC_Lay_Daily'!$B:$B, $A22) | L22: =SUM(B22:K22) | M22: =AVERAGE(B22:K22)
A23: Grand Total | B23: =SUM(B18:B22) | C23: =SUM(C18:C22) | D23: =SUM(D18:D22) | E23: =SUM(E18:E22) | F23: =SUM(F18:F22) | G23: =SUM(G18:G22) | H23: =SUM(H18:H22) | I23: =SUM(I18:I22) | ... M23: =SUM(M18:M22)
A26: 3. VOLUME GIAO THEO SÀN (Event 8.8)
A27: Sàn / Kênh | B27: 06/08 | C27: 07/08 | D27: 08/08 | E27: 09/08 | F27: 10/08 | G27: 11/08 | H27: 12/08 | I27: 13/08 | J27: 14/08 | K27: 15/08 | L27: Tổng 10 ngày | M27: Trung bình
A28: Shopee | B28: =SUMIFS('7_FC_Giao_Daily'!AB:AB, '7_FC_Giao_Daily'!$E:$E, $A28) | C28: =SUMIFS('7_FC_Giao_Daily'!AC:AC, '7_FC_Giao_Daily'!$E:$E, $A28) | D28: =SUMIFS('7_FC_Giao_Daily'!AD:AD, '7_FC_Giao_Daily'!$E:$E, $A28) | E28: =SUMIFS('7_FC_Giao_Daily'!AE:AE, '7_FC_Giao_Daily'!$E:$E, $A28) | F28: =SUMIFS('7_FC_Giao_Daily'!AF:AF, '7_FC_Giao_Daily'!$E:$E, $A28) | G28: =SUMIFS('7_FC_Giao_Daily'!AG:AG, '7_FC_Giao_Daily'!$E:$E, $A28) | H28: =SUMIFS('7_FC_Giao_Daily'!AH:AH, '7_FC_Giao_Daily'!$E:$E, $A28) | I28: =SUMIFS('7_FC_Giao_Daily'!AI:AI, '7_FC_Giao_Daily'!$E:$E, $A28) | J28: =SUMIFS('7_FC_Giao_Daily'!AJ:AJ, '7_FC_Giao_Daily'!$E:$E, $A28) | K28: =SUMIFS('7_FC_Giao_Daily'!AK:AK, '7_FC_Giao_Daily'!$E:$E, $A28) | L28: =SUM(B28:K28) | M28: =AVERAGE(B28:K28)
A29: Shopee-Bulky | B29: =SUMIFS('7_FC_Giao_Daily'!AB:AB, '7_FC_Giao_Daily'!$E:$E, $A29) | C29: =SUMIFS('7_FC_Giao_Daily'!AC:AC, '7_FC_Giao_Daily'!$E:$E, $A29) | D29: =SUMIFS('7_FC_Giao_Daily'!AD:AD, '7_FC_Giao_Daily'!$E:$E, $A29) | E29: =SUMIFS('7_FC_Giao_Daily'!AE:AE, '7_FC_Giao_Daily'!$E:$E, $A29) | F29: =SUMIFS('7_FC_Giao_Daily'!AF:AF, '7_FC_Giao_Daily'!$E:$E, $A29) | G29: =SUMIFS('7_FC_Giao_Daily'!AG:AG, '7_FC_Giao_Daily'!$E:$E, $A29) | H29: =SUMIFS('7_FC_Giao_Daily'!AH:AH, '7_FC_Giao_Daily'!$E:$E, $A29) | I29: =SUMIFS('7_FC_Giao_Daily'!AI:AI, '7_FC_Giao_Daily'!$E:$E, $A29) | J29: =SUMIFS('7_FC_Giao_Daily'!AJ:AJ, '7_FC_Giao_Daily'!$E:$E, $A29) | K29: =SUMIFS('7_FC_Giao_Daily'!AK:AK, '7_FC_Giao_Daily'!$E:$E, $A29) | L29: =SUM(B29:K29) | M29: =AVERAGE(B29:K29)
A30: Shopee-Bulky (10-15kg) | B30: =SUMIFS('7_FC_Giao_Daily'!AB:AB, '7_FC_Giao_Daily'!$E:$E, $A30) | C30: =SUMIFS('7_FC_Giao_Daily'!AC:AC, '7_FC_Giao_Daily'!$E:$E, $A30) | D30: =SUMIFS('7_FC_Giao_Daily'!AD:AD, '7_FC_Giao_Daily'!$E:$E, $A30) | E30: =SUMIFS('7_FC_Giao_Daily'!AE:AE, '7_FC_Giao_Daily'!$E:$E, $A30) | F30: =SUMIFS('7_FC_Giao_Daily'!AF:AF, '7_FC_Giao_Daily'!$E:$E, $A30) | G30: =SUMIFS('7_FC_Giao_Daily'!AG:AG, '7_FC_Giao_Daily'!$E:$E, $A30) | H30: =SUMIFS('7_FC_Giao_Daily'!AH:AH, '7_FC_Giao_Daily'!$E:$E, $A30) | I30: =SUMIFS('7_FC_Giao_Daily'!AI:AI, '7_FC_Giao_Daily'!$E:$E, $A30) | J30: =SUMIFS('7_FC_Giao_Daily'!AJ:AJ, '7_FC_Giao_Daily'!$E:$E, $A30) | K30: =SUMIFS('7_FC_Giao_Daily'!AK:AK, '7_FC_Giao_Daily'!$E:$E, $A30) | L30: =SUM(B30:K30) | M30: =AVERAGE(B30:K30)
A31: SME | B31: =SUMIFS('7_FC_Giao_Daily'!AB:AB, '7_FC_Giao_Daily'!$E:$E, $A31) | C31: =SUMIFS('7_FC_Giao_Daily'!AC:AC, '7_FC_Giao_Daily'!$E:$E, $A31) | D31: =SUMIFS('7_FC_Giao_Daily'!AD:AD, '7_FC_Giao_Daily'!$E:$E, $A31) | E31: =SUMIFS('7_FC_Giao_Daily'!AE:AE, '7_FC_Giao_Daily'!$E:$E, $A31) | F31: =SUMIFS('7_FC_Giao_Daily'!AF:AF, '7_FC_Giao_Daily'!$E:$E, $A31) | G31: =SUMIFS('7_FC_Giao_Daily'!AG:AG, '7_FC_Giao_Daily'!$E:$E, $A31) | H31: =SUMIFS('7_FC_Giao_Daily'!AH:AH, '7_FC_Giao_Daily'!$E:$E, $A31) | I31: =SUMIFS('7_FC_Giao_Daily'!AI:AI, '7_FC_Giao_Daily'!$E:$E, $A31) | J31: =SUMIFS('7_FC_Giao_Daily'!AJ:AJ, '7_FC_Giao_Daily'!$E:$E, $A31) | K31: =SUMIFS('7_FC_Giao_Daily'!AK:AK, '7_FC_Giao_Daily'!$E:$E, $A31) | L31: =SUM(B31:K31) | M31: =AVERAGE(B31:K31)
A32: SME-Bulky | B32: =SUMIFS('7_FC_Giao_Daily'!AB:AB, '7_FC_Giao_Daily'!$E:$E, $A32) | C32: =SUMIFS('7_FC_Giao_Daily'!AC:AC, '7_FC_Giao_Daily'!$E:$E, $A32) | D32: =SUMIFS('7_FC_Giao_Daily'!AD:AD, '7_FC_Giao_Daily'!$E:$E, $A32) | E32: =SUMIFS('7_FC_Giao_Daily'!AE:AE, '7_FC_Giao_Daily'!$E:$E, $A32) | F32: =SUMIFS('7_FC_Giao_Daily'!AF:AF, '7_FC_Giao_Daily'!$E:$E, $A32) | G32: =SUMIFS('7_FC_Giao_Daily'!AG:AG, '7_FC_Giao_Daily'!$E:$E, $A32) | H32: =SUMIFS('7_FC_Giao_Daily'!AH:AH, '7_FC_Giao_Daily'!$E:$E, $A32) | I32: =SUMIFS('7_FC_Giao_Daily'!AI:AI, '7_FC_Giao_Daily'!$E:$E, $A32) | J32: =SUMIFS('7_FC_Giao_Daily'!AJ:AJ, '7_FC_Giao_Daily'!$E:$E, $A32) | K32: =SUMIFS('7_FC_Giao_Daily'!AK:AK, '7_FC_Giao_Daily'!$E:$E, $A32) | L32: =SUM(B32:K32) | M32: =AVERAGE(B32:K32)
A33: TTS | B33: =SUMIFS('7_FC_Giao_Daily'!AB:AB, '7_FC_Giao_Daily'!$E:$E, $A33) | C33: =SUMIFS('7_FC_Giao_Daily'!AC:AC, '7_FC_Giao_Daily'!$E:$E, $A33) | D33: =SUMIFS('7_FC_Giao_Daily'!AD:AD, '7_FC_Giao_Daily'!$E:$E, $A33) | E33: =SUMIFS('7_FC_Giao_Daily'!AE:AE, '7_FC_Giao_Daily'!$E:$E, $A33) | F33: =SUMIFS('7_FC_Giao_Daily'!AF:AF, '7_FC_Giao_Daily'!$E:$E, $A33) | G33: =SUMIFS('7_FC_Giao_Daily'!AG:AG, '7_FC_Giao_Daily'!$E:$E, $A33) | H33: =SUMIFS('7_FC_Giao_Daily'!AH:AH, '7_FC_Giao_Daily'!$E:$E, $A33) | I33: =SUMIFS('7_FC_Giao_Daily'!AI:AI, '7_FC_Giao_Daily'!$E:$E, $A33) | J33: =SUMIFS('7_FC_Giao_Daily'!AJ:AJ, '7_FC_Giao_Daily'!$E:$E, $A33) | K33: =SUMIFS('7_FC_Giao_Daily'!AK:AK, '7_FC_Giao_Daily'!$E:$E, $A33) | L33: =SUM(B33:K33) | M33: =AVERAGE(B33:K33)
A34: TTS-Bulky | B34: =SUMIFS('7_FC_Giao_Daily'!AB:AB, '7_FC_Giao_Daily'!$E:$E, $A34) | C34: =SUMIFS('7_FC_Giao_Daily'!AC:AC, '7_FC_Giao_Daily'!$E:$E, $A34) | D34: =SUMIFS('7_FC_Giao_Daily'!AD:AD, '7_FC_Giao_Daily'!$E:$E, $A34) | E34: =SUMIFS('7_FC_Giao_Daily'!AE:AE, '7_FC_Giao_Daily'!$E:$E, $A34) | F34: =SUMIFS('7_FC_Giao_Daily'!AF:AF, '7_FC_Giao_Daily'!$E:$E, $A34) | G34: =SUMIFS('7_FC_Giao_Daily'!AG:AG, '7_FC_Giao_Daily'!$E:$E, $A34) | H34: =SUMIFS('7_FC_Giao_Daily'!AH:AH, '7_FC_Giao_Daily'!$E:$E, $A34) | I34: =SUMIFS('7_FC_Giao_Daily'!AI:AI, '7_FC_Giao_Daily'!$E:$E, $A34) | J34: =SUMIFS('7_FC_Giao_Daily'!AJ:AJ, '7_FC_Giao_Daily'!$E:$E, $A34) | K34: =SUMIFS('7_FC_Giao_Daily'!AK:AK, '7_FC_Giao_Daily'!$E:$E, $A34) | L34: =SUM(B34:K34) | M34: =AVERAGE(B34:K34)
A35: Grand Total | B35: =SUM(B28:B34) | C35: =SUM(C28:C34) | D35: =SUM(D28:D34) | E35: =SUM(E28:E34) | F35: =SUM(F28:F34) | G35: =SUM(G28:G34) | H35: =SUM(H28:H34) | I35: =SUM(I28:I34) | ... M35: =SUM(M28:M34)
A38: 4. VOLUME GIAO THEO TỈNH/QUẬN (Event 8.8)
A39: Tỉnh / Quận | B39: 06/08 | C39: 07/08 | D39: 08/08 | E39: 09/08 | F39: 10/08 | G39: 11/08 | H39: 12/08 | I39: 13/08 | J39: 14/08 | K39: 15/08 | L39: Tổng 10 ngày | M39: Trung bình
A40: Bình Thuận | B40: =SUMIFS('7_FC_Giao_Daily'!AB:AB, '7_FC_Giao_Daily'!$B:$B, $A40) | C40: =SUMIFS('7_FC_Giao_Daily'!AC:AC, '7_FC_Giao_Daily'!$B:$B, $A40) | D40: =SUMIFS('7_FC_Giao_Daily'!AD:AD, '7_FC_Giao_Daily'!$B:$B, $A40) | E40: =SUMIFS('7_FC_Giao_Daily'!AE:AE, '7_FC_Giao_Daily'!$B:$B, $A40) | F40: =SUMIFS('7_FC_Giao_Daily'!AF:AF, '7_FC_Giao_Daily'!$B:$B, $A40) | G40: =SUMIFS('7_FC_Giao_Daily'!AG:AG, '7_FC_Giao_Daily'!$B:$B, $A40) | H40: =SUMIFS('7_FC_Giao_Daily'!AH:AH, '7_FC_Giao_Daily'!$B:$B, $A40) | I40: =SUMIFS('7_FC_Giao_Daily'!AI:AI, '7_FC_Giao_Daily'!$B:$B, $A40) | J40: =SUMIFS('7_FC_Giao_Daily'!AJ:AJ, '7_FC_Giao_Daily'!$B:$B, $A40) | K40: =SUMIFS('7_FC_Giao_Daily'!AK:AK, '7_FC_Giao_Daily'!$B:$B, $A40) | L40: =SUM(B40:K40) | M40: =AVERAGE(B40:K40)
A41: Khánh Hòa | B41: =SUMIFS('7_FC_Giao_Daily'!AB:AB, '7_FC_Giao_Daily'!$B:$B, $A41) | C41: =SUMIFS('7_FC_Giao_Daily'!AC:AC, '7_FC_Giao_Daily'!$B:$B, $A41) | D41: =SUMIFS('7_FC_Giao_Daily'!AD:AD, '7_FC_Giao_Daily'!$B:$B, $A41) | E41: =SUMIFS('7_FC_Giao_Daily'!AE:AE, '7_FC_Giao_Daily'!$B:$B, $A41) | F41: =SUMIFS('7_FC_Giao_Daily'!AF:AF, '7_FC_Giao_Daily'!$B:$B, $A41) | G41: =SUMIFS('7_FC_Giao_Daily'!AG:AG, '7_FC_Giao_Daily'!$B:$B, $A41) | H41: =SUMIFS('7_FC_Giao_Daily'!AH:AH, '7_FC_Giao_Daily'!$B:$B, $A41) | I41: =SUMIFS('7_FC_Giao_Daily'!AI:AI, '7_FC_Giao_Daily'!$B:$B, $A41) | J41: =SUMIFS('7_FC_Giao_Daily'!AJ:AJ, '7_FC_Giao_Daily'!$B:$B, $A41) | K41: =SUMIFS('7_FC_Giao_Daily'!AK:AK, '7_FC_Giao_Daily'!$B:$B, $A41) | L41: =SUM(B41:K41) | M41: =AVERAGE(B41:K41)
A42: Lâm Đồng | B42: =SUMIFS('7_FC_Giao_Daily'!AB:AB, '7_FC_Giao_Daily'!$B:$B, $A42) | C42: =SUMIFS('7_FC_Giao_Daily'!AC:AC, '7_FC_Giao_Daily'!$B:$B, $A42) | D42: =SUMIFS('7_FC_Giao_Daily'!AD:AD, '7_FC_Giao_Daily'!$B:$B, $A42) | E42: =SUMIFS('7_FC_Giao_Daily'!AE:AE, '7_FC_Giao_Daily'!$B:$B, $A42) | F42: =SUMIFS('7_FC_Giao_Daily'!AF:AF, '7_FC_Giao_Daily'!$B:$B, $A42) | G42: =SUMIFS('7_FC_Giao_Daily'!AG:AG, '7_FC_Giao_Daily'!$B:$B, $A42) | H42: =SUMIFS('7_FC_Giao_Daily'!AH:AH, '7_FC_Giao_Daily'!$B:$B, $A42) | I42: =SUMIFS('7_FC_Giao_Daily'!AI:AI, '7_FC_Giao_Daily'!$B:$B, $A42) | J42: =SUMIFS('7_FC_Giao_Daily'!AJ:AJ, '7_FC_Giao_Daily'!$B:$B, $A42) | K42: =SUMIFS('7_FC_Giao_Daily'!AK:AK, '7_FC_Giao_Daily'!$B:$B, $A42) | L42: =SUM(B42:K42) | M42: =AVERAGE(B42:K42)
A43: Ninh Thuận | B43: =SUMIFS('7_FC_Giao_Daily'!AB:AB, '7_FC_Giao_Daily'!$B:$B, $A43) | C43: =SUMIFS('7_FC_Giao_Daily'!AC:AC, '7_FC_Giao_Daily'!$B:$B, $A43) | D43: =SUMIFS('7_FC_Giao_Daily'!AD:AD, '7_FC_Giao_Daily'!$B:$B, $A43) | E43: =SUMIFS('7_FC_Giao_Daily'!AE:AE, '7_FC_Giao_Daily'!$B:$B, $A43) | F43: =SUMIFS('7_FC_Giao_Daily'!AF:AF, '7_FC_Giao_Daily'!$B:$B, $A43) | G43: =SUMIFS('7_FC_Giao_Daily'!AG:AG, '7_FC_Giao_Daily'!$B:$B, $A43) | H43: =SUMIFS('7_FC_Giao_Daily'!AH:AH, '7_FC_Giao_Daily'!$B:$B, $A43) | I43: =SUMIFS('7_FC_Giao_Daily'!AI:AI, '7_FC_Giao_Daily'!$B:$B, $A43) | J43: =SUMIFS('7_FC_Giao_Daily'!AJ:AJ, '7_FC_Giao_Daily'!$B:$B, $A43) | K43: =SUMIFS('7_FC_Giao_Daily'!AK:AK, '7_FC_Giao_Daily'!$B:$B, $A43) | L43: =SUM(B43:K43) | M43: =AVERAGE(B43:K43)
A44: Đắk Nông | B44: =SUMIFS('7_FC_Giao_Daily'!AB:AB, '7_FC_Giao_Daily'!$B:$B, $A44) | C44: =SUMIFS('7_FC_Giao_Daily'!AC:AC, '7_FC_Giao_Daily'!$B:$B, $A44) | D44: =SUMIFS('7_FC_Giao_Daily'!AD:AD, '7_FC_Giao_Daily'!$B:$B, $A44) | E44: =SUMIFS('7_FC_Giao_Daily'!AE:AE, '7_FC_Giao_Daily'!$B:$B, $A44) | F44: =SUMIFS('7_FC_Giao_Daily'!AF:AF, '7_FC_Giao_Daily'!$B:$B, $A44) | G44: =SUMIFS('7_FC_Giao_Daily'!AG:AG, '7_FC_Giao_Daily'!$B:$B, $A44) | H44: =SUMIFS('7_FC_Giao_Daily'!AH:AH, '7_FC_Giao_Daily'!$B:$B, $A44) | I44: =SUMIFS('7_FC_Giao_Daily'!AI:AI, '7_FC_Giao_Daily'!$B:$B, $A44) | J44: =SUMIFS('7_FC_Giao_Daily'!AJ:AJ, '7_FC_Giao_Daily'!$B:$B, $A44) | K44: =SUMIFS('7_FC_Giao_Daily'!AK:AK, '7_FC_Giao_Daily'!$B:$B, $A44) | L44: =SUM(B44:K44) | M44: =AVERAGE(B44:K44)
A45: Grand Total | B45: =SUM(B40:B44) | C45: =SUM(C40:C44) | D45: =SUM(D40:D44) | E45: =SUM(E40:E44) | F45: =SUM(F40:F44) | G45: =SUM(G40:G44) | H45: =SUM(H40:H44) | I45: =SUM(I40:I44) | ... M45: =SUM(M40:M44)
A48: 5. BẢNG TÍNH COMBO CHART (VOLUME, TRUNG BÌNH, % TĂNG/GIẢM FC)
A49: A. FC Volume Lấy event 08.08 (Style Combo Chart)
...

Sheet Thủy
A1: 1. VOLUME LẤY THEO KH (Event 8.8)
A2: Sàn / Kênh | B2: 06/08 | C2: 07/08 | D2: 08/08 | E2: 09/08 | F2: 10/08 | G2: 11/08 | H2: 12/08 | I2: 13/08 | J2: 14/08 | K2: 15/08 | L2: Tổng 10 ngày | M2: Trung bình
A3: Shopee | B3: =SUMIFS('6_FC_Lay_Daily'!AB:AB, '6_FC_Lay_Daily'!$E:$E, $A3) | C3: =SUMIFS('6_FC_Lay_Daily'!AC:AC, '6_FC_Lay_Daily'!$E:$E, $A3) | D3: =SUMIFS('6_FC_Lay_Daily'!AD:AD, '6_FC_Lay_Daily'!$E:$E, $A3) | E3: =SUMIFS('6_FC_Lay_Daily'!AE:AE, '6_FC_Lay_Daily'!$E:$E, $A3) | F3: =SUMIFS('6_FC_Lay_Daily'!AF:AF, '6_FC_Lay_Daily'!$E:$E, $A3) | G3: =SUMIFS('6_FC_Lay_Daily'!AG:AG, '6_FC_Lay_Daily'!$E:$E, $A3) | H3: =SUMIFS('6_FC_Lay_Daily'!AH:AH, '6_FC_Lay_Daily'!$E:$E, $A3) | I3: =SUMIFS('6_FC_Lay_Daily'!AI:AI, '6_FC_Lay_Daily'!$E:$E, $A3) | J3: =SUMIFS('6_FC_Lay_Daily'!AJ:AJ, '6_FC_Lay_Daily'!$E:$E, $A3) | K3: =SUMIFS('6_FC_Lay_Daily'!AK:AK, '6_FC_Lay_Daily'!$E:$E, $A3) | L3: =SUM(B3:K3) | M3: =AVERAGE(B3:K3)
A4: Shopee-Bulky | B4: =SUMIFS('6_FC_Lay_Daily'!AB:AB, '6_FC_Lay_Daily'!$E:$E, $A4) | C4: =SUMIFS('6_FC_Lay_Daily'!AC:AC, '6_FC_Lay_Daily'!$E:$E, $A4) | D4: =SUMIFS('6_FC_Lay_Daily'!AD:AD, '6_FC_Lay_Daily'!$E:$E, $A4) | E4: =SUMIFS('6_FC_Lay_Daily'!AE:AE, '6_FC_Lay_Daily'!$E:$E, $A4) | F4: =SUMIFS('6_FC_Lay_Daily'!AF:AF, '6_FC_Lay_Daily'!$E:$E, $A4) | G4: =SUMIFS('6_FC_Lay_Daily'!AG:AG, '6_FC_Lay_Daily'!$E:$E, $A4) | H4: =SUMIFS('6_FC_Lay_Daily'!AH:AH, '6_FC_Lay_Daily'!$E:$E, $A4) | I4: =SUMIFS('6_FC_Lay_Daily'!AI:AI, '6_FC_Lay_Daily'!$E:$E, $A4) | J4: =SUMIFS('6_FC_Lay_Daily'!AJ:AJ, '6_FC_Lay_Daily'!$E:$E, $A4) | K4: =SUMIFS('6_FC_Lay_Daily'!AK:AK, '6_FC_Lay_Daily'!$E:$E, $A4) | L4: =SUM(B4:K4) | M4: =AVERAGE(B4:K4)
A5: Shopee-Bulky (10-15kg) | B5: =SUMIFS('6_FC_Lay_Daily'!AB:AB, '6_FC_Lay_Daily'!$E:$E, $A5) | C5: =SUMIFS('6_FC_Lay_Daily'!AC:AC, '6_FC_Lay_Daily'!$E:$E, $A5) | D5: =SUMIFS('6_FC_Lay_Daily'!AD:AD, '6_FC_Lay_Daily'!$E:$E, $A5) | E5: =SUMIFS('6_FC_Lay_Daily'!AE:AE, '6_FC_Lay_Daily'!$E:$E, $A5) | F5: =SUMIFS('6_FC_Lay_Daily'!AF:AF, '6_FC_Lay_Daily'!$E:$E, $A5) | G5: =SUMIFS('6_FC_Lay_Daily'!AG:AG, '6_FC_Lay_Daily'!$E:$E, $A5) | H5: =SUMIFS('6_FC_Lay_Daily'!AH:AH, '6_FC_Lay_Daily'!$E:$E, $A5) | I5: =SUMIFS('6_FC_Lay_Daily'!AI:AI, '6_FC_Lay_Daily'!$E:$E, $A5) | J5: =SUMIFS('6_FC_Lay_Daily'!AJ:AJ, '6_FC_Lay_Daily'!$E:$E, $A5) | K5: =SUMIFS('6_FC_Lay_Daily'!AK:AK, '6_FC_Lay_Daily'!$E:$E, $A5) | L5: =SUM(B5:K5) | M5: =AVERAGE(B5:K5)
A6: SME | B6: =SUMIFS('6_FC_Lay_Daily'!AB:AB, '6_FC_Lay_Daily'!$E:$E, $A6) | C6: =SUMIFS('6_FC_Lay_Daily'!AC:AC, '6_FC_Lay_Daily'!$E:$E, $A6) | D6: =SUMIFS('6_FC_Lay_Daily'!AD:AD, '6_FC_Lay_Daily'!$E:$E, $A6) | E6: =SUMIFS('6_FC_Lay_Daily'!AE:AE, '6_FC_Lay_Daily'!$E:$E, $A6) | F6: =SUMIFS('6_FC_Lay_Daily'!AF:AF, '6_FC_Lay_Daily'!$E:$E, $A6) | G6: =SUMIFS('6_FC_Lay_Daily'!AG:AG, '6_FC_Lay_Daily'!$E:$E, $A6) | H6: =SUMIFS('6_FC_Lay_Daily'!AH:AH, '6_FC_Lay_Daily'!$E:$E, $A6) | I6: =SUMIFS('6_FC_Lay_Daily'!AI:AI, '6_FC_Lay_Daily'!$E:$E, $A6) | J6: =SUMIFS('6_FC_Lay_Daily'!AJ:AJ, '6_FC_Lay_Daily'!$E:$E, $A6) | K6: =SUMIFS('6_FC_Lay_Daily'!AK:AK, '6_FC_Lay_Daily'!$E:$E, $A6) | L6: =SUM(B6:K6) | M6: =AVERAGE(B6:K6)
A7: SME-Bulky | B7: =SUMIFS('6_FC_Lay_Daily'!AB:AB, '6_FC_Lay_Daily'!$E:$E, $A7) | C7: =SUMIFS('6_FC_Lay_Daily'!AC:AC, '6_FC_Lay_Daily'!$E:$E, $A7) | D7: =SUMIFS('6_FC_Lay_Daily'!AD:AD, '6_FC_Lay_Daily'!$E:$E, $A7) | E7: =SUMIFS('6_FC_Lay_Daily'!AE:AE, '6_FC_Lay_Daily'!$E:$E, $A7) | F7: =SUMIFS('6_FC_Lay_Daily'!AF:AF, '6_FC_Lay_Daily'!$E:$E, $A7) | G7: =SUMIFS('6_FC_Lay_Daily'!AG:AG, '6_FC_Lay_Daily'!$E:$E, $A7) | H7: =SUMIFS('6_FC_Lay_Daily'!AH:AH, '6_FC_Lay_Daily'!$E:$E, $A7) | I7: =SUMIFS('6_FC_Lay_Daily'!AI:AI, '6_FC_Lay_Daily'!$E:$E, $A7) | J7: =SUMIFS('6_FC_Lay_Daily'!AJ:AJ, '6_FC_Lay_Daily'!$E:$E, $A7) | K7: =SUMIFS('6_FC_Lay_Daily'!AK:AK, '6_FC_Lay_Daily'!$E:$E, $A7) | L7: =SUM(B7:K7) | M7: =AVERAGE(B7:K7)
A8: TTS | B8: =SUMIFS('6_FC_Lay_Daily'!AB:AB, '6_FC_Lay_Daily'!$E:$E, $A8) | C8: =SUMIFS('6_FC_Lay_Daily'!AC:AC, '6_FC_Lay_Daily'!$E:$E, $A8) | D8: =SUMIFS('6_FC_Lay_Daily'!AD:AD, '6_FC_Lay_Daily'!$E:$E, $A8) | E8: =SUMIFS('6_FC_Lay_Daily'!AE:AE, '6_FC_Lay_Daily'!$E:$E, $A8) | F8: =SUMIFS('6_FC_Lay_Daily'!AF:AF, '6_FC_Lay_Daily'!$E:$E, $A8) | G8: =SUMIFS('6_FC_Lay_Daily'!AG:AG, '6_FC_Lay_Daily'!$E:$E, $A8) | H8: =SUMIFS('6_FC_Lay_Daily'!AH:AH, '6_FC_Lay_Daily'!$E:$E, $A8) | I8: =SUMIFS('6_FC_Lay_Daily'!AI:AI, '6_FC_Lay_Daily'!$E:$E, $A8) | J8: =SUMIFS('6_FC_Lay_Daily'!AJ:AJ, '6_FC_Lay_Daily'!$E:$E, $A8) | K8: =SUMIFS('6_FC_Lay_Daily'!AK:AK, '6_FC_Lay_Daily'!$E:$E, $A8) | L8: =SUM(B8:K8) | M8: =AVERAGE(B8:K8)
A9: TTS-Bulky | B9: =SUMIFS('6_FC_Lay_Daily'!AB:AB, '6_FC_Lay_Daily'!$E:$E, $A9) | C9: =SUMIFS('6_FC_Lay_Daily'!AC:AC, '6_FC_Lay_Daily'!$E:$E, $A9) | D9: =SUMIFS('6_FC_Lay_Daily'!AD:AD, '6_FC_Lay_Daily'!$E:$E, $A9) | E9: =SUMIFS('6_FC_Lay_Daily'!AE:AE, '6_FC_Lay_Daily'!$E:$E, $A9) | F9: =SUMIFS('6_FC_Lay_Daily'!AF:AF, '6_FC_Lay_Daily'!$E:$E, $A9) | G9: =SUMIFS('6_FC_Lay_Daily'!AG:AG, '6_FC_Lay_Daily'!$E:$E, $A9) | H9: =SUMIFS('6_FC_Lay_Daily'!AH:AH, '6_FC_Lay_Daily'!$E:$E, $A9) | I9: =SUMIFS('6_FC_Lay_Daily'!AI:AI, '6_FC_Lay_Daily'!$E:$E, $A9) | J9: =SUMIFS('6_FC_Lay_Daily'!AJ:AJ, '6_FC_Lay_Daily'!$E:$E, $A9) | K9: =SUMIFS('6_FC_Lay_Daily'!AK:AK, '6_FC_Lay_Daily'!$E:$E, $A9) | L9: =SUM(B9:K9) | M9: =AVERAGE(B9:K9)
A10: Grand Total | B10: =SUM(B3:B9) | C10: =SUM(C3:C9) | D10: =SUM(D3:D9) | E10: =SUM(E3:E9) | F10: =SUM(F3:F9) | G10: =SUM(G3:G9) | H10: =SUM(H3:H9) | I10: =SUM(I3:I9) | ... M10: =SUM(M3:M9)
A13: 2. VOLUME LẤY THEO TỈNH (Event 8.8)
A14: Tỉnh / Quận | B14: 06/08 | C14: 07/08 | D14: 08/08 | E14: 09/08 | F14: 10/08 | G14: 11/08 | H14: 12/08 | I14: 13/08 | J14: 14/08 | K14: 15/08 | L14: Tổng 10 ngày | M14: Trung bình
A15: Bình Thuận | B15: =SUMIFS('6_FC_Lay_Daily'!AB:AB, '6_FC_Lay_Daily'!$B:$B, $A15) | C15: =SUMIFS('6_FC_Lay_Daily'!AC:AC, '6_FC_Lay_Daily'!$B:$B, $A15) | D15: =SUMIFS('6_FC_Lay_Daily'!AD:AD, '6_FC_Lay_Daily'!$B:$B, $A15) | E15: =SUMIFS('6_FC_Lay_Daily'!AE:AE, '6_FC_Lay_Daily'!$B:$B, $A15) | F15: =SUMIFS('6_FC_Lay_Daily'!AF:AF, '6_FC_Lay_Daily'!$B:$B, $A15) | G15: =SUMIFS('6_FC_Lay_Daily'!AG:AG, '6_FC_Lay_Daily'!$B:$B, $A15) | H15: =SUMIFS('6_FC_Lay_Daily'!AH:AH, '6_FC_Lay_Daily'!$B:$B, $A15) | I15: =SUMIFS('6_FC_Lay_Daily'!AI:AI, '6_FC_Lay_Daily'!$B:$B, $A15) | J15: =SUMIFS('6_FC_Lay_Daily'!AJ:AJ, '6_FC_Lay_Daily'!$B:$B, $A15) | K15: =SUMIFS('6_FC_Lay_Daily'!AK:AK, '6_FC_Lay_Daily'!$B:$B, $A15) | L15: =SUM(B15:K15) | M15: =AVERAGE(B15:K15)
A16: Khánh Hòa | B16: =SUMIFS('6_FC_Lay_Daily'!AB:AB, '6_FC_Lay_Daily'!$B:$B, $A16) | C16: =SUMIFS('6_FC_Lay_Daily'!AC:AC, '6_FC_Lay_Daily'!$B:$B, $A16) | D16: =SUMIFS('6_FC_Lay_Daily'!AD:AD, '6_FC_Lay_Daily'!$B:$B, $A16) | E16: =SUMIFS('6_FC_Lay_Daily'!AE:AE, '6_FC_Lay_Daily'!$B:$B, $A16) | F16: =SUMIFS('6_FC_Lay_Daily'!AF:AF, '6_FC_Lay_Daily'!$B:$B, $A16) | G16: =SUMIFS('6_FC_Lay_Daily'!AG:AG, '6_FC_Lay_Daily'!$B:$B, $A16) | H16: =SUMIFS('6_FC_Lay_Daily'!AH:AH, '6_FC_Lay_Daily'!$B:$B, $A16) | I16: =SUMIFS('6_FC_Lay_Daily'!AI:AI, '6_FC_Lay_Daily'!$B:$B, $A16) | J16: =SUMIFS('6_FC_Lay_Daily'!AJ:AJ, '6_FC_Lay_Daily'!$B:$B, $A16) | K16: =SUMIFS('6_FC_Lay_Daily'!AK:AK, '6_FC_Lay_Daily'!$B:$B, $A16) | L16: =SUM(B16:K16) | M16: =AVERAGE(B16:K16)
A17: Lâm Đồng | B17: =SUMIFS('6_FC_Lay_Daily'!AB:AB, '6_FC_Lay_Daily'!$B:$B, $A17) | C17: =SUMIFS('6_FC_Lay_Daily'!AC:AC, '6_FC_Lay_Daily'!$B:$B, $A17) | D17: =SUMIFS('6_FC_Lay_Daily'!AD:AD, '6_FC_Lay_Daily'!$B:$B, $A17) | E17: =SUMIFS('6_FC_Lay_Daily'!AE:AE, '6_FC_Lay_Daily'!$B:$B, $A17) | F17: =SUMIFS('6_FC_Lay_Daily'!AF:AF, '6_FC_Lay_Daily'!$B:$B, $A17) | G17: =SUMIFS('6_FC_Lay_Daily'!AG:AG, '6_FC_Lay_Daily'!$B:$B, $A17) | H17: =SUMIFS('6_FC_Lay_Daily'!AH:AH, '6_FC_Lay_Daily'!$B:$B, $A17) | I17: =SUMIFS('6_FC_Lay_Daily'!AI:AI, '6_FC_Lay_Daily'!$B:$B, $A17) | J17: =SUMIFS('6_FC_Lay_Daily'!AJ:AJ, '6_FC_Lay_Daily'!$B:$B, $A17) | K17: =SUMIFS('6_FC_Lay_Daily'!AK:AK, '6_FC_Lay_Daily'!$B:$B, $A17) | L17: =SUM(B17:K17) | M17: =AVERAGE(B17:K17)
A18: Ninh Thuận | B18: =SUMIFS('6_FC_Lay_Daily'!AB:AB, '6_FC_Lay_Daily'!$B:$B, $A18) | C18: =SUMIFS('6_FC_Lay_Daily'!AC:AC, '6_FC_Lay_Daily'!$B:$B, $A18) | D18: =SUMIFS('6_FC_Lay_Daily'!AD:AD, '6_FC_Lay_Daily'!$B:$B, $A18) | E18: =SUMIFS('6_FC_Lay_Daily'!AE:AE, '6_FC_Lay_Daily'!$B:$B, $A18) | F18: =SUMIFS('6_FC_Lay_Daily'!AF:AF, '6_FC_Lay_Daily'!$B:$B, $A18) | G18: =SUMIFS('6_FC_Lay_Daily'!AG:AG, '6_FC_Lay_Daily'!$B:$B, $A18) | H18: =SUMIFS('6_FC_Lay_Daily'!AH:AH, '6_FC_Lay_Daily'!$B:$B, $A18) | I18: =SUMIFS('6_FC_Lay_Daily'!AI:AI, '6_FC_Lay_Daily'!$B:$B, $A18) | J18: =SUMIFS('6_FC_Lay_Daily'!AJ:AJ, '6_FC_Lay_Daily'!$B:$B, $A18) | K18: =SUMIFS('6_FC_Lay_Daily'!AK:AK, '6_FC_Lay_Daily'!$B:$B, $A18) | L18: =SUM(B18:K18) | M18: =AVERAGE(B18:K18)
A19: Đắk Nông | B19: =SUMIFS('6_FC_Lay_Daily'!AB:AB, '6_FC_Lay_Daily'!$B:$B, $A19) | C19: =SUMIFS('6_FC_Lay_Daily'!AC:AC, '6_FC_Lay_Daily'!$B:$B, $A19) | D19: =SUMIFS('6_FC_Lay_Daily'!AD:AD, '6_FC_Lay_Daily'!$B:$B, $A19) | E19: =SUMIFS('6_FC_Lay_Daily'!AE:AE, '6_FC_Lay_Daily'!$B:$B, $A19) | F19: =SUMIFS('6_FC_Lay_Daily'!AF:AF, '6_FC_Lay_Daily'!$B:$B, $A19) | G19: =SUMIFS('6_FC_Lay_Daily'!AG:AG, '6_FC_Lay_Daily'!$B:$B, $A19) | H19: =SUMIFS('6_FC_Lay_Daily'!AH:AH, '6_FC_Lay_Daily'!$B:$B, $A19) | I19: =SUMIFS('6_FC_Lay_Daily'!AI:AI, '6_FC_Lay_Daily'!$B:$B, $A19) | J19: =SUMIFS('6_FC_Lay_Daily'!AJ:AJ, '6_FC_Lay_Daily'!$B:$B, $A19) | K19: =SUMIFS('6_FC_Lay_Daily'!AK:AK, '6_FC_Lay_Daily'!$B:$B, $A19) | L19: =SUM(B19:K19) | M19: =AVERAGE(B19:K19)
A20: Grand Total | B20: =SUM(B15:B19) | C20: =SUM(C15:C19) | D20: =SUM(D15:D19) | E20: =SUM(E15:E19) | F20: =SUM(F15:F19) | G20: =SUM(G15:G19) | H20: =SUM(H15:H19) | I20: =SUM(I15:I19) | ... M20: =SUM(M15:M19)
A23: 3. VOLUME GIAO THEO KH (Event 8.8)
A24: Sàn / Kênh | B24: 06/08 | C24: 07/08 | D24: 08/08 | E24: 09/08 | F24: 10/08 | G24: 11/08 | H24: 12/08 | I24: 13/08 | J24: 14/08 | K24: 15/08 | L24: Tổng 10 ngày | M24: Trung bình
A25: Shopee | B25: =SUMIFS('7_FC_Giao_Daily'!AB:AB, '7_FC_Giao_Daily'!$E:$E, $A25) | C25: =SUMIFS('7_FC_Giao_Daily'!AC:AC, '7_FC_Giao_Daily'!$E:$E, $A25) | D25: =SUMIFS('7_FC_Giao_Daily'!AD:AD, '7_FC_Giao_Daily'!$E:$E, $A25) | E25: =SUMIFS('7_FC_Giao_Daily'!AE:AE, '7_FC_Giao_Daily'!$E:$E, $A25) | F25: =SUMIFS('7_FC_Giao_Daily'!AF:AF, '7_FC_Giao_Daily'!$E:$E, $A25) | G25: =SUMIFS('7_FC_Giao_Daily'!AG:AG, '7_FC_Giao_Daily'!$E:$E, $A25) | H25: =SUMIFS('7_FC_Giao_Daily'!AH:AH, '7_FC_Giao_Daily'!$E:$E, $A25) | I25: =SUMIFS('7_FC_Giao_Daily'!AI:AI, '7_FC_Giao_Daily'!$E:$E, $A25) | J25: =SUMIFS('7_FC_Giao_Daily'!AJ:AJ, '7_FC_Giao_Daily'!$E:$E, $A25) | K25: =SUMIFS('7_FC_Giao_Daily'!AK:AK, '7_FC_Giao_Daily'!$E:$E, $A25) | L25: =SUM(B25:K25) | M25: =AVERAGE(B25:K25)
A26: Shopee-Bulky | B26: =SUMIFS('7_FC_Giao_Daily'!AB:AB, '7_FC_Giao_Daily'!$E:$E, $A26) | C26: =SUMIFS('7_FC_Giao_Daily'!AC:AC, '7_FC_Giao_Daily'!$E:$E, $A26) | D26: =SUMIFS('7_FC_Giao_Daily'!AD:AD, '7_FC_Giao_Daily'!$E:$E, $A26) | E26: =SUMIFS('7_FC_Giao_Daily'!AE:AE, '7_FC_Giao_Daily'!$E:$E, $A26) | F26: =SUMIFS('7_FC_Giao_Daily'!AF:AF, '7_FC_Giao_Daily'!$E:$E, $A26) | G26: =SUMIFS('7_FC_Giao_Daily'!AG:AG, '7_FC_Giao_Daily'!$E:$E, $A26) | H26: =SUMIFS('7_FC_Giao_Daily'!AH:AH, '7_FC_Giao_Daily'!$E:$E, $A26) | I26: =SUMIFS('7_FC_Giao_Daily'!AI:AI, '7_FC_Giao_Daily'!$E:$E, $A26) | J26: =SUMIFS('7_FC_Giao_Daily'!AJ:AJ, '7_FC_Giao_Daily'!$E:$E, $A26) | K26: =SUMIFS('7_FC_Giao_Daily'!AK:AK, '7_FC_Giao_Daily'!$E:$E, $A26) | L26: =SUM(B26:K26) | M26: =AVERAGE(B26:K26)
A27: Shopee-Bulky (10-15kg) | B27: =SUMIFS('7_FC_Giao_Daily'!AB:AB, '7_FC_Giao_Daily'!$E:$E, $A27) | C27: =SUMIFS('7_FC_Giao_Daily'!AC:AC, '7_FC_Giao_Daily'!$E:$E, $A27) | D27: =SUMIFS('7_FC_Giao_Daily'!AD:AD, '7_FC_Giao_Daily'!$E:$E, $A27) | E27: =SUMIFS('7_FC_Giao_Daily'!AE:AE, '7_FC_Giao_Daily'!$E:$E, $A27) | F27: =SUMIFS('7_FC_Giao_Daily'!AF:AF, '7_FC_Giao_Daily'!$E:$E, $A27) | G27: =SUMIFS('7_FC_Giao_Daily'!AG:AG, '7_FC_Giao_Daily'!$E:$E, $A27) | H27: =SUMIFS('7_FC_Giao_Daily'!AH:AH, '7_FC_Giao_Daily'!$E:$E, $A27) | I27: =SUMIFS('7_FC_Giao_Daily'!AI:AI, '7_FC_Giao_Daily'!$E:$E, $A27) | J27: =SUMIFS('7_FC_Giao_Daily'!AJ:AJ, '7_FC_Giao_Daily'!$E:$E, $A27) | K27: =SUMIFS('7_FC_Giao_Daily'!AK:AK, '7_FC_Giao_Daily'!$E:$E, $A27) | L27: =SUM(B27:K27) | M27: =AVERAGE(B27:K27)
A28: SME | B28: =SUMIFS('7_FC_Giao_Daily'!AB:AB, '7_FC_Giao_Daily'!$E:$E, $A28) | C28: =SUMIFS('7_FC_Giao_Daily'!AC:AC, '7_FC_Giao_Daily'!$E:$E, $A28) | D28: =SUMIFS('7_FC_Giao_Daily'!AD:AD, '7_FC_Giao_Daily'!$E:$E, $A28) | E28: =SUMIFS('7_FC_Giao_Daily'!AE:AE, '7_FC_Giao_Daily'!$E:$E, $A28) | F28: =SUMIFS('7_FC_Giao_Daily'!AF:AF, '7_FC_Giao_Daily'!$E:$E, $A28) | G28: =SUMIFS('7_FC_Giao_Daily'!AG:AG, '7_FC_Giao_Daily'!$E:$E, $A28) | H28: =SUMIFS('7_FC_Giao_Daily'!AH:AH, '7_FC_Giao_Daily'!$E:$E, $A28) | I28: =SUMIFS('7_FC_Giao_Daily'!AI:AI, '7_FC_Giao_Daily'!$E:$E, $A28) | J28: =SUMIFS('7_FC_Giao_Daily'!AJ:AJ, '7_FC_Giao_Daily'!$E:$E, $A28) | K28: =SUMIFS('7_FC_Giao_Daily'!AK:AK, '7_FC_Giao_Daily'!$E:$E, $A28) | L28: =SUM(B28:K28) | M28: =AVERAGE(B28:K28)
A29: SME-Bulky | B29: =SUMIFS('7_FC_Giao_Daily'!AB:AB, '7_FC_Giao_Daily'!$E:$E, $A29) | C29: =SUMIFS('7_FC_Giao_Daily'!AC:AC, '7_FC_Giao_Daily'!$E:$E, $A29) | D29: =SUMIFS('7_FC_Giao_Daily'!AD:AD, '7_FC_Giao_Daily'!$E:$E, $A29) | E29: =SUMIFS('7_FC_Giao_Daily'!AE:AE, '7_FC_Giao_Daily'!$E:$E, $A29) | F29: =SUMIFS('7_FC_Giao_Daily'!AF:AF, '7_FC_Giao_Daily'!$E:$E, $A29) | G29: =SUMIFS('7_FC_Giao_Daily'!AG:AG, '7_FC_Giao_Daily'!$E:$E, $A29) | H29: =SUMIFS('7_FC_Giao_Daily'!AH:AH, '7_FC_Giao_Daily'!$E:$E, $A29) | I29: =SUMIFS('7_FC_Giao_Daily'!AI:AI, '7_FC_Giao_Daily'!$E:$E, $A29) | J29: =SUMIFS('7_FC_Giao_Daily'!AJ:AJ, '7_FC_Giao_Daily'!$E:$E, $A29) | K29: =SUMIFS('7_FC_Giao_Daily'!AK:AK, '7_FC_Giao_Daily'!$E:$E, $A29) | L29: =SUM(B29:K29) | M29: =AVERAGE(B29:K29)
A30: TTS | B30: =SUMIFS('7_FC_Giao_Daily'!AB:AB, '7_FC_Giao_Daily'!$E:$E, $A30) | C30: =SUMIFS('7_FC_Giao_Daily'!AC:AC, '7_FC_Giao_Daily'!$E:$E, $A30) | D30: =SUMIFS('7_FC_Giao_Daily'!AD:AD, '7_FC_Giao_Daily'!$E:$E, $A30) | E30: =SUMIFS('7_FC_Giao_Daily'!AE:AE, '7_FC_Giao_Daily'!$E:$E, $A30) | F30: =SUMIFS('7_FC_Giao_Daily'!AF:AF, '7_FC_Giao_Daily'!$E:$E, $A30) | G30: =SUMIFS('7_FC_Giao_Daily'!AG:AG, '7_FC_Giao_Daily'!$E:$E, $A30) | H30: =SUMIFS('7_FC_Giao_Daily'!AH:AH, '7_FC_Giao_Daily'!$E:$E, $A30) | I30: =SUMIFS('7_FC_Giao_Daily'!AI:AI, '7_FC_Giao_Daily'!$E:$E, $A30) | J30: =SUMIFS('7_FC_Giao_Daily'!AJ:AJ, '7_FC_Giao_Daily'!$E:$E, $A30) | K30: =SUMIFS('7_FC_Giao_Daily'!AK:AK, '7_FC_Giao_Daily'!$E:$E, $A30) | L30: =SUM(B30:K30) | M30: =AVERAGE(B30:K30)
A31: TTS-Bulky | B31: =SUMIFS('7_FC_Giao_Daily'!AB:AB, '7_FC_Giao_Daily'!$E:$E, $A31) | C31: =SUMIFS('7_FC_Giao_Daily'!AC:AC, '7_FC_Giao_Daily'!$E:$E, $A31) | D31: =SUMIFS('7_FC_Giao_Daily'!AD:AD, '7_FC_Giao_Daily'!$E:$E, $A31) | E31: =SUMIFS('7_FC_Giao_Daily'!AE:AE, '7_FC_Giao_Daily'!$E:$E, $A31) | F31: =SUMIFS('7_FC_Giao_Daily'!AF:AF, '7_FC_Giao_Daily'!$E:$E, $A31) | G31: =SUMIFS('7_FC_Giao_Daily'!AG:AG, '7_FC_Giao_Daily'!$E:$E, $A31) | H31: =SUMIFS('7_FC_Giao_Daily'!AH:AH, '7_FC_Giao_Daily'!$E:$E, $A31) | I31: =SUMIFS('7_FC_Giao_Daily'!AI:AI, '7_FC_Giao_Daily'!$E:$E, $A31) | J31: =SUMIFS('7_FC_Giao_Daily'!AJ:AJ, '7_FC_Giao_Daily'!$E:$E, $A31) | K31: =SUMIFS('7_FC_Giao_Daily'!AK:AK, '7_FC_Giao_Daily'!$E:$E, $A31) | L31: =SUM(B31:K31) | M31: =AVERAGE(B31:K31)
A32: Grand Total | B32: =SUM(B25:B31) | C32: =SUM(C25:C31) | D32: =SUM(D25:D31) | E32: =SUM(E25:E31) | F32: =SUM(F25:F31) | G32: =SUM(G25:G31) | H32: =SUM(H25:H31) | I32: =SUM(I25:I31) | ... M32: =SUM(M25:M31)
A35: 4. VOLUME GIAO THEO TỈNH (Event 8.8)
A36: Tỉnh / Quận | B36: 06/08 | C36: 07/08 | D36: 08/08 | E36: 09/08 | F36: 10/08 | G36: 11/08 | H36: 12/08 | I36: 13/08 | J36: 14/08 | K36: 15/08 | L36: Tổng 10 ngày | M36: Trung bình
A37: Bình Thuận | B37: =SUMIFS('7_FC_Giao_Daily'!AB:AB, '7_FC_Giao_Daily'!$B:$B, $A37) | C37: =SUMIFS('7_FC_Giao_Daily'!AC:AC, '7_FC_Giao_Daily'!$B:$B, $A37) | D37: =SUMIFS('7_FC_Giao_Daily'!AD:AD, '7_FC_Giao_Daily'!$B:$B, $A37) | E37: =SUMIFS('7_FC_Giao_Daily'!AE:AE, '7_FC_Giao_Daily'!$B:$B, $A37) | F37: =SUMIFS('7_FC_Giao_Daily'!AF:AF, '7_FC_Giao_Daily'!$B:$B, $A37) | G37: =SUMIFS('7_FC_Giao_Daily'!AG:AG, '7_FC_Giao_Daily'!$B:$B, $A37) | H37: =SUMIFS('7_FC_Giao_Daily'!AH:AH, '7_FC_Giao_Daily'!$B:$B, $A37) | I37: =SUMIFS('7_FC_Giao_Daily'!AI:AI, '7_FC_Giao_Daily'!$B:$B, $A37) | J37: =SUMIFS('7_FC_Giao_Daily'!AJ:AJ, '7_FC_Giao_Daily'!$B:$B, $A37) | K37: =SUMIFS('7_FC_Giao_Daily'!AK:AK, '7_FC_Giao_Daily'!$B:$B, $A37) | L37: =SUM(B37:K37) | M37: =AVERAGE(B37:K37)
A38: Khánh Hòa | B38: =SUMIFS('7_FC_Giao_Daily'!AB:AB, '7_FC_Giao_Daily'!$B:$B, $A38) | C38: =SUMIFS('7_FC_Giao_Daily'!AC:AC, '7_FC_Giao_Daily'!$B:$B, $A38) | D38: =SUMIFS('7_FC_Giao_Daily'!AD:AD, '7_FC_Giao_Daily'!$B:$B, $A38) | E38: =SUMIFS('7_FC_Giao_Daily'!AE:AE, '7_FC_Giao_Daily'!$B:$B, $A38) | F38: =SUMIFS('7_FC_Giao_Daily'!AF:AF, '7_FC_Giao_Daily'!$B:$B, $A38) | G38: =SUMIFS('7_FC_Giao_Daily'!AG:AG, '7_FC_Giao_Daily'!$B:$B, $A38) | H38: =SUMIFS('7_FC_Giao_Daily'!AH:AH, '7_FC_Giao_Daily'!$B:$B, $A38) | I38: =SUMIFS('7_FC_Giao_Daily'!AI:AI, '7_FC_Giao_Daily'!$B:$B, $A38) | J38: =SUMIFS('7_FC_Giao_Daily'!AJ:AJ, '7_FC_Giao_Daily'!$B:$B, $A38) | K38: =SUMIFS('7_FC_Giao_Daily'!AK:AK, '7_FC_Giao_Daily'!$B:$B, $A38) | L38: =SUM(B38:K38) | M38: =AVERAGE(B38:K38)
A39: Lâm Đồng | B39: =SUMIFS('7_FC_Giao_Daily'!AB:AB, '7_FC_Giao_Daily'!$B:$B, $A39) | C39: =SUMIFS('7_FC_Giao_Daily'!AC:AC, '7_FC_Giao_Daily'!$B:$B, $A39) | D39: =SUMIFS('7_FC_Giao_Daily'!AD:AD, '7_FC_Giao_Daily'!$B:$B, $A39) | E39: =SUMIFS('7_FC_Giao_Daily'!AE:AE, '7_FC_Giao_Daily'!$B:$B, $A39) | F39: =SUMIFS('7_FC_Giao_Daily'!AF:AF, '7_FC_Giao_Daily'!$B:$B, $A39) | G39: =SUMIFS('7_FC_Giao_Daily'!AG:AG, '7_FC_Giao_Daily'!$B:$B, $A39) | H39: =SUMIFS('7_FC_Giao_Daily'!AH:AH, '7_FC_Giao_Daily'!$B:$B, $A39) | I39: =SUMIFS('7_FC_Giao_Daily'!AI:AI, '7_FC_Giao_Daily'!$B:$B, $A39) | J39: =SUMIFS('7_FC_Giao_Daily'!AJ:AJ, '7_FC_Giao_Daily'!$B:$B, $A39) | K39: =SUMIFS('7_FC_Giao_Daily'!AK:AK, '7_FC_Giao_Daily'!$B:$B, $A39) | L39: =SUM(B39:K39) | M39: =AVERAGE(B39:K39)
A40: Ninh Thuận | B40: =SUMIFS('7_FC_Giao_Daily'!AB:AB, '7_FC_Giao_Daily'!$B:$B, $A40) | C40: =SUMIFS('7_FC_Giao_Daily'!AC:AC, '7_FC_Giao_Daily'!$B:$B, $A40) | D40: =SUMIFS('7_FC_Giao_Daily'!AD:AD, '7_FC_Giao_Daily'!$B:$B, $A40) | E40: =SUMIFS('7_FC_Giao_Daily'!AE:AE, '7_FC_Giao_Daily'!$B:$B, $A40) | F40: =SUMIFS('7_FC_Giao_Daily'!AF:AF, '7_FC_Giao_Daily'!$B:$B, $A40) | G40: =SUMIFS('7_FC_Giao_Daily'!AG:AG, '7_FC_Giao_Daily'!$B:$B, $A40) | H40: =SUMIFS('7_FC_Giao_Daily'!AH:AH, '7_FC_Giao_Daily'!$B:$B, $A40) | I40: =SUMIFS('7_FC_Giao_Daily'!AI:AI, '7_FC_Giao_Daily'!$B:$B, $A40) | J40: =SUMIFS('7_FC_Giao_Daily'!AJ:AJ, '7_FC_Giao_Daily'!$B:$B, $A40) | K40: =SUMIFS('7_FC_Giao_Daily'!AK:AK, '7_FC_Giao_Daily'!$B:$B, $A40) | L40: =SUM(B40:K40) | M40: =AVERAGE(B40:K40)
A41: Đắk Nông | B41: =SUMIFS('7_FC_Giao_Daily'!AB:AB, '7_FC_Giao_Daily'!$B:$B, $A41) | C41: =SUMIFS('7_FC_Giao_Daily'!AC:AC, '7_FC_Giao_Daily'!$B:$B, $A41) | D41: =SUMIFS('7_FC_Giao_Daily'!AD:AD, '7_FC_Giao_Daily'!$B:$B, $A41) | E41: =SUMIFS('7_FC_Giao_Daily'!AE:AE, '7_FC_Giao_Daily'!$B:$B, $A41) | F41: =SUMIFS('7_FC_Giao_Daily'!AF:AF, '7_FC_Giao_Daily'!$B:$B, $A41) | G41: =SUMIFS('7_FC_Giao_Daily'!AG:AG, '7_FC_Giao_Daily'!$B:$B, $A41) | H41: =SUMIFS('7_FC_Giao_Daily'!AH:AH, '7_FC_Giao_Daily'!$B:$B, $A41) | I41: =SUMIFS('7_FC_Giao_Daily'!AI:AI, '7_FC_Giao_Daily'!$B:$B, $A41) | J41: =SUMIFS('7_FC_Giao_Daily'!AJ:AJ, '7_FC_Giao_Daily'!$B:$B, $A41) | K41: =SUMIFS('7_FC_Giao_Daily'!AK:AK, '7_FC_Giao_Daily'!$B:$B, $A41) | L41: =SUM(B41:K41) | M41: =AVERAGE(B41:K41)
A42: Grand Total | B42: =SUM(B37:B41) | C42: =SUM(C37:C41) | D42: =SUM(D37:D41) | E42: =SUM(E37:E41) | F42: =SUM(F37:F41) | G42: =SUM(G37:G41) | H42: =SUM(H37:H41) | I42: =SUM(I37:I41) | ... M42: =SUM(M37:M41)
A45: 5. BẢNG TÍNH COMBO CHART (VOLUME, TRUNG BÌNH, % TĂNG/GIẢM FC)
A46: A. FC Volume Lấy event 08.08
A47: Chỉ tiêu | B47: 06/08 | C47: 07/08 | D47: 08/08 | E47: 09/08 | F47: 10/08 | G47: 11/08 | H47: 12/08 | I47: 13/08 | J47: 14/08 | K47: 15/08 | L47: Trung bình toàn đợt
A48: Volume lấy | B48: =B10 | C48: =C10 | D48: =D10 | E48: =E10 | F48: =F10 | G48: =G10 | H48: =H10 | I48: =I10 | ... K48: =K10 | L48: =AVERAGE(B48:K48)
...

Sheet 0_README
A1: STT | B1: Mục | C1: Nội_Dung
A2: 0 | B2: ━━━ HƯỚNG DẪN VÙNG NTB ━━━
B3: ━━━ PHÂN BIỆT 2 NHÓM SỐ (QUAN TRỌNG) ━━━
A4: A | B4: ① Sheet 0–5: NHÓM TOPLINE (số AOP) | C4: Sản lượng theo AOP — KẾ HOẠCH KINH DOANH NĂM của Công ty. CỐ ĐỊNH dài hạn; chỉ thay đổi khi có DEAL LỚN hoặc rà soát ĐỊNH KỲ 6 THÁNG/LẦN. Đây là số trần/khung từ trên đưa xuống → Vùng CHỈ XEM, không cân chỉnh.
A5: B | B5: ② Sheet 6–7: NHÓM DỰ BÁO (Forecast) | C5: Sản lượng DỰ KIẾN HÀNG THÁNG — dự báo kết hợp: (1) kế hoạch tháng của khách hàng + (2) dữ liệu dự báo từ thực tế quá khứ. Do team Capacity TRỰC TIẾP cân chỉnh & dự báo (cùng Vùng) → cập nhật ngắn hạn + lên phương án ứng phó. Đây là số LINH HOẠT theo tháng.
B6: ↳ Tóm lại | C6: TOPLINE = khung năm cố định (AOP, đổi 6 tháng/lần). FORECAST = dự báo tháng linh hoạt (Capacity + Vùng cân chỉnh).
A7: 1 | B7: MỤC ĐÍCH | C7: File giúp Vùng nắm: (1) sản lượng B2B từng phường + BC tiếp nhận; (2) sản lượng giao của BC thường. Vùng dùng để lập kế hoạch năng lực + thuê xe khi cần.
A8: 2 | B8: CÁCH XỬ LÝ VẬN HÀNH (ngoài file)
A9: 2a | B9: BC tự giao được | C9: BC địa phương đủ năng lực (xe + nhân sự + chỗ) → BC tự xử lý.
A10: 2b | B10: BC không tự giao được | C10: Vùng sắp xếp phương án ngoài: thuê xe tải / nhờ BC khác / giải pháp năng lực phù hợp từng tuyến. Quyết định vận hành nằm ngoài file này.
A11: 3 | B11: CÁC SHEET
A12: 3a | B12: 1_Config_Chuan | C12: Cấu hình hệ thống đang chạy cho từng phường: BC lấy / BC giao, nhóm B2B, ngưỡng khối lượng cũ–mới. Chỉ để tham khảo, không sửa.
A13: 3b | B13: 3_KQ_BC_Detail | C13: Sản lượng BC thường giao (không gồm B2B), theo BC × dải khối lượng × tháng.
A14: 3c | B14: 4_KQ_B2B | C14: Sản lượng B2B phân bổ theo phường × tháng (nhóm A/B/C + ngưỡng + BC tiếp nhận). Là sản lượng phân bổ, không phải sheet thao tác.
A15: 3d | B15: 5_CuMoi_Thang | C15: So sánh sản lượng CŨ (ngưỡng GXT) và MỚI (15kg) theo từng tháng + chênh lệch số đơn để Vùng chuẩn bị năng lực.
A16: 3e | B16: 6_FC_Lay_Daily | C16: Dự báo Lấy hàng theo BC × ngày.
A17: 3f | B17: 7_FC_Giao_Daily | C17: Dự báo Giao hàng theo BC × ngày.
A18: 4 | B18: ━━━ ĐỊNH NGHĨA NHÓM B2B ━━━ | C18: Tham chiếu cột Nhóm B2B trong các sheet
A19: 4a | B19: Nhóm A — B2B xử lý 100% | C19: Toàn bộ sản lượng đủ điều kiện theo ngưỡng khối lượng được phân về B2B / Giao Hàng Nặng.
A20: 4b | B20: Nhóm B — B2B xử lý theo tỷ lệ x% | C20: Chỉ x% sản lượng đủ điều kiện theo ngưỡng được phân về B2B. Tỷ lệ x% áp cho TOÀN BỘ đơn đủ điều kiện tại phường, KHÔNG chỉ đơn Ecom.
A21: 4c | B21: Nhóm C — Không xử lý B2B | C21: Sản lượng KHÔNG phân về B2B; đi theo BC thường tùy cấu hình.
A22: 5 | B22: CŨ / MỚI là gì? | C22: CŨ = ngưỡng khối lượng GXT đang vận hành (tham khảo). MỚI = mốc 15kg thống nhất áp dụng. Phân bổ sản lượng theo mốc MỚI.
A23: 6 | B23: LIÊN HỆ | C23: Vấn đề kỹ thuật: ducbd@ghn.vn
B24: Cập nhật lần cuối | C24: 46175

Sheet 1_Config_Chuan
A1: Tỉnh | B1: Quận_ID | C1: Quận_Tên | D1: Phường_ID | E1: Phường_Tên | F1: BC_Lấy_ID | G1: BC_Lấy_Tên | H1: BC_Giao_ID | I1: BC_Giao_Tên | J1: B2B_Mở | K1: B2B_Nhóm | L1: B2B_Pct | M1: B2B_Từ_kg_CŨ_GXT | N1: B2B_Từ_kg_MỚI | O1: B2B_Status | P1: Ngày_Mở
A2: Khánh Hòa | B2: 1548 | C2: Thành phố Nha Trang | D2: 410101 | E2: Phường Lộc Thọ | F2: 20495000 | G2: Bưu Cục 40A Yết Kiêu-Nha Trang-Khánh Hòa | H2: 20495000 | I2: Bưu Cục 40A Yết Kiêu-Nha Trang-Khánh Hòa | J2: TRUE | K2: C | L2: 0 | O2: Đã mở
A3: Khánh Hòa | B3: 1548 | C3: Thành phố Nha Trang | D3: 410102 | E3: Phường Ngọc Hiệp | F3: 20320000 | G3: Bưu Cục 466 Đường 23/10-Nha Trang-Khánh Hòa | H3: 20320000 | I3: Bưu Cục 466 Đường 23/10-Nha Trang-Khánh Hòa | J3: TRUE | K3: B | L3: 0.7 | M3: 15 | N3: 15 | O3: Đã mở
A4: Khánh Hòa | B4: 1548 | C4: Thành phố Nha Trang | D4: 410103 | E4: Phường Phước Hải | F4: 22363000 | G4: Bưu Cục Đường 35 Hà Quang 1-Xã Nam Nha Trang-Khánh Hòa | H4: 22363000 | I4: Bưu Cục Đường 35 Hà Quang 1-Xã Nam Nha Trang-Khánh Hòa | J4: TRUE | K4: B | L4: 0.7 | M4: 15 | N4: 15 | O4: Đã mở
A5: Khánh Hòa | B5: 1548 | C5: Thành phố Nha Trang | D5: 410104 | E5: Phường Phước Hòa | F5: 22704000 | G5: Bưu Cục 06 Lê Hồng Phong-TP.Nha Trang-Khánh Hòa | H5: 22704000 | I5: Bưu Cục 06 Lê Hồng Phong-TP.Nha Trang-Khánh Hòa | J5: TRUE | K5: B | L5: 0.7 | M5: 20 | N5: 15 | O5: Đã mở
A6: Khánh Hòa | B6: 1548 | C6: Thành phố Nha Trang | D6: 410105 | E6: Phường Phước Long | F6: 22746000 | G6: Bưu Cục 229 Phước Long-Nam Nha Trang-Khánh Hòa | H6: 22746000 | I6: Bưu Cục 229 Phước Long-Nam Nha Trang-Khánh Hòa | J6: TRUE | K6: B | L6: 0.7 | M6: 20 | N6: 15 | O6: Đã mở
A7: Khánh Hòa | B7: 1548 | C7: Thành phố Nha Trang | D7: 410106 | E7: Phường Phước Tân | F7: 22704000 | G7: Bưu Cục 06 Lê Hồng Phong-TP.Nha Trang-Khánh Hòa | H7: 22704000 | I7: Bưu Cục 06 Lê Hồng Phong-TP.Nha Trang-Khánh Hòa | J7: TRUE | K7: C | L7: 0 | O7: Đã mở
A8: Khánh Hòa | B8: 1548 | C8: Thành phố Nha Trang | D8: 410107 | E8: Phường Phước Tiến | F8: 22704000 | G8: Bưu Cục 06 Lê Hồng Phong-TP.Nha Trang-Khánh Hòa | H8: 22704000 | I8: Bưu Cục 06 Lê Hồng Phong-TP.Nha Trang-Khánh Hòa | J8: TRUE | K8: C | L8: 0 | O8: Đã mở
A9: Khánh Hòa | B9: 1548 | C9: Thành phố Nha Trang | D9: 410108 | E9: Phường Phương Sài | F9: 22704000 | G9: Bưu Cục 06 Lê Hồng Phong-TP.Nha Trang-Khánh Hòa | H9: 22704000 | I9: Bưu Cục 06 Lê Hồng Phong-TP.Nha Trang-Khánh Hòa | J9: TRUE | K9: C | L9: 0 | O9: Đã mở
A10: Khánh Hòa | B10: 1548 | C10: Thành phố Nha Trang | D10: 410109 | E10: Phường Phương Sơn | F10: 20320000 | G10: Bưu Cục 466 Đường 23/10-Nha Trang-Khánh Hòa | H10: 20320000 | I10: Bưu Cục 466 Đường 23/10-Nha Trang-Khánh Hòa | J10: TRUE | K10: C | L10: 0 | O10: Đã mở
A11: Khánh Hòa | B11: 1548 | C11: Thành phố Nha Trang | D11: 410110 | E11: Phường Tân Lập | F11: 22704000 | G11: Bưu Cục 06 Lê Hồng Phong-TP.Nha Trang-Khánh Hòa | H11: 22704000 | I11: Bưu Cục 06 Lê Hồng Phong-TP.Nha Trang-Khánh Hòa | J11: TRUE | K11: B | L11: 0.7 | M11: 15 | N11: 15 | O11: Đã mở
A12: Khánh Hòa | B12: 1548 | C12: Thành phố Nha Trang | D12: 410111 | E12: Phường Vạn Thắng | F12: 20495000 | G12: Bưu Cục 40A Yết Kiêu-Nha Trang-Khánh Hòa | H12: 20495000 | I12: Bưu Cục 40A Yết Kiêu-Nha Trang-Khánh Hòa | J12: TRUE | K12: C | L12: 0 | O12: Đã mở
A13: Khánh Hòa | B13: 1548 | C13: Thành phố Nha Trang | D13: 410112 | E13: Phường Vạn Thạnh | F13: 20495000 | G13: Bưu Cục 40A Yết Kiêu-Nha Trang-Khánh Hòa | H13: 20495000 | I13: Bưu Cục 40A Yết Kiêu-Nha Trang-Khánh Hòa | J13: TRUE | K13: C | L13: 0 | O13: Đã mở
A14: Khánh Hòa | B14: 1548 | C14: Thành phố Nha Trang | D14: 410113 | E14: Phường Vĩnh Hải | F14: 2399 | G14: Bưu Cục 195 Đường 2/4-Nha Trang-Khánh Hòa | H14: 2399 | I14: Bưu Cục 195 Đường 2/4-Nha Trang-Khánh Hòa | J14: TRUE | K14: B | L14: 0.7 | M14: 15 | N14: 15 | O14: Đã mở
A15: Khánh Hòa | B15: 1548 | C15: Thành phố Nha Trang | D15: 410114 | E15: Phường Vĩnh Hòa | F15: 2399 | G15: Bưu Cục 195 Đường 2/4-Nha Trang-Khánh Hòa | H15: 2399 | I15: Bưu Cục 195 Đường 2/4-Nha Trang-Khánh Hòa | J15: TRUE | K15: B | L15: 0.7 | M15: 15 | N15: 15 | O15: Đã mở
A16: Khánh Hòa | B16: 1548 | C16: Thành phố Nha Trang | D16: 410115 | E16: Phường Vĩnh Nguyên | F16: 22746000 | G16: Bưu Cục 229 Phước Long-Nam Nha Trang-Khánh Hòa | H16: 22746000 | I16: Bưu Cục 229 Phước Long-Nam Nha Trang-Khánh Hòa | J16: TRUE | K16: B | L16: 0.7 | M16: 20 | N16: 15 | O16: Đã mở
A17: Khánh Hòa | B17: 1548 | C17: Thành phố Nha Trang | D17: 410116 | E17: Phường Vĩnh Phước | F17: 2399 | G17: Bưu Cục 195 Đường 2/4-Nha Trang-Khánh Hòa | H17: 2399 | I17: Bưu Cục 195 Đường 2/4-Nha Trang-Khánh Hòa | J17: TRUE | K17: B | L17: 0.7 | M17: 15 | N17: 15 | O17: Đã mở
A18: Khánh Hòa | B18: 1548 | C18: Thành phố Nha Trang | D18: 410117 | E18: Phường Vĩnh Thọ | F18: 2399 | G18: Bưu Cục 195 Đường 2/4-Nha Trang-Khánh Hòa | H18: 2399 | I18: Bưu Cục 195 Đường 2/4-Nha Trang-Khánh Hòa | J18: TRUE | K18: C | L18: 0 | O18: Đã mở
A19: Khánh Hòa | B19: 1548 | C19: Thành phố Nha Trang | D19: 410118 | E19: Phường Vĩnh Trường | F19: 22746000 | G19: Bưu Cục 229 Phước Long-Nam Nha Trang-Khánh Hòa | H19: 22746000 | I19: Bưu Cục 229 Phước Long-Nam Nha Trang-Khánh Hòa | J19: TRUE | K19: C | L19: 0 | O19: Đã mở
A20: Khánh Hòa | B20: 1548 | C20: Thành phố Nha Trang | D20: 410119 | E20: Phường Xương Huân | F20: 20495000 | G20: Bưu Cục 40A Yết Kiêu-Nha Trang-Khánh Hòa | H20: 20495000 | I20: Bưu Cục 40A Yết Kiêu-Nha Trang-Khánh Hòa | J20: TRUE | K20: C | L20: 0 | O20: Đã mở
A21: Khánh Hòa | B21: 1548 | C21: Thành phố Nha Trang | D21: 410120 | E21: Xã Phước Đồng | F21: 2502 | G21: Bưu Cục Phước Đồng-Nha Trang-Khánh Hoà | H21: 2502 | I21: Bưu Cục Phước Đồng-Nha Trang-Khánh Hoà | J21: TRUE | K21: B | L21: 0.7 | M21: 20 | N21: 15 | O21: Đã mở
A22: Khánh Hòa | B22: 1548 | C22: Thành phố Nha Trang | D22: 410121 | E22: Xã Vĩnh Hiệp | F22: 20320000 | G22: Bưu Cục 466 Đường 23/10-Nha Trang-Khánh Hòa | H22: 20320000 | I22: Bưu Cục 466 Đường 23/10-Nha Trang-Khánh Hòa | J22: TRUE | K22: B | L22: 0.7 | M22: 15 | N22: 15 | O22: Đã mở
A23: Khánh Hòa | B23: 1548 | C23: Thành phố Nha Trang | D23: 410122 | E23: Xã Vĩnh Lương | F23: 2399 | G23: Bưu Cục 195 Đường 2/4-Nha Trang-Khánh Hòa | H23: 2399 | I23: Bưu Cục 195 Đường 2/4-Nha Trang-Khánh Hòa | J23: TRUE | K23: B | L23: 0.7 | M23: 15 | N23: 15 | O23: Đã mở
A24: Khánh Hòa | B24: 1548 | C24: Thành phố Nha Trang | D24: 410123 | E24: Xã Vĩnh Ngọc | F24: 20320000 | G24: Bưu Cục 466 Đường 23/10-Nha Trang-Khánh Hòa | H24: 20320000 | I24: Bưu Cục 466 Đường 23/10-Nha Trang-Khánh Hòa | J24: TRUE | K24: C | L24: 0 | O24: Đã mở
A25: Khánh Hòa | B25: 1548 | C25: Thành phố Nha Trang | D25: 410124 | E25: Xã Vĩnh Phương | F25: 2399 | G25: Bưu Cục 195 Đường 2/4-Nha Trang-Khánh Hòa | H25: 2399 | I25: Bưu Cục 195 Đường 2/4-Nha Trang-Khánh Hòa | J25: TRUE | K25: C | L25: 0 | O25: Đã mở
A26: Khánh Hòa | B26: 1548 | C26: Thành phố Nha Trang | D26: 410125 | E26: Xã Vĩnh Thái | F26: 22363000 | G26: Bưu Cục Đường 35 Hà Quang 1-Xã Nam Nha Trang-Khánh Hòa | H26: 22363000 | I26: Bưu Cục Đường 35 Hà Quang 1-Xã Nam Nha Trang-Khánh Hòa | J26: TRUE | K26: B | L26: 0.7 | M26: 20 | N26: 15 | O26: Đã mở
A27: Khánh Hòa | B27: 1548 | C27: Thành phố Nha Trang | D27: 410126 | E27: Xã Vĩnh Thạnh | F27: 22774000 | G27: Bưu Cục Thôn Phú An Nam 2-Xã Diên Khánh-Khánh Hòa | H27: 22774000 | I27: Bưu Cục Thôn Phú An Nam 2-Xã Diên Khánh-Khánh Hòa | J27: TRUE | K27: B | L27: 0.7 | M27: 15 | N27: 15 | O27: Đã mở
A28: Khánh Hòa | B28: 1548 | C28: Thành phố Nha Trang | D28: 410127 | E28: Xã Vĩnh Trung | F28: 22774000 | G28: Bưu Cục Thôn Phú An Nam 2-Xã Diên Khánh-Khánh Hòa | H28: 22774000 | I28: Bưu Cục Thôn Phú An Nam 2-Xã Diên Khánh-Khánh Hòa | J28: TRUE | K28: C | L28: 0 | O28: Đã mở
A29: Khánh Hòa | B29: 1548 | C29: Thành phố Nha Trang | D29: 91590 | E29: Phường Tân Tiến | F29: 22704000 | G29: Bưu Cục 06 Lê Hồng Phong-TP.Nha Trang-Khánh Hòa | H29: 22704000 | I29: Bưu Cục 06 Lê Hồng Phong-TP.Nha Trang-Khánh Hòa | J29: FALSE | K29: C | L29: 0 | O29: Chưa mở
A30: Lâm Đồng | B30: 1550 | C30: Thành phố Đà Lạt | D30: 420101 | E30: Phường 1 | F30: 21687000 | G30: Bưu Cục Cao Bá Quát-Phường 7-Đà Lạt-Lâm Đồng | H30: 21687000 | I30: Bưu Cục Cao Bá Quát-Phường 7-Đà Lạt-Lâm Đồng | J30: TRUE | K30: A | L30: 1 | M30: 15 | N30: 15 | O30: Đã mở
A31: Lâm Đồng | B31: 1550 | C31: Thành phố Đà Lạt | D31: 420102 | E31: Phường 10 | F31: 22312000 | G31: Bưu Cục Số 6 Trương Văn Hoàn-Phường 9-Đà Lạt-Lâm Đồng | H31: 22312000 | I31: Bưu Cục Số 6 Trương Văn Hoàn-Phường 9-Đà Lạt-Lâm Đồng | J31: TRUE | K31: A | L31: 1 | M31: 16 | N31: 15 | O31: Đã mở
A32: Lâm Đồng | B32: 1550 | C32: Thành phố Đà Lạt | D32: 420103 | E32: Phường 11 | F32: 22116000 | G32: Bưu Cục 300 Tự Phước-Đà Lạt-Lâm Đồng | H32: 22116000 | I32: Bưu Cục 300 Tự Phước-Đà Lạt-Lâm Đồng | J32: TRUE | K32: A | L32: 1 | M32: 16 | N32: 15 | O32: Đã mở
A33: Lâm Đồng | B33: 1550 | C33: Thành phố Đà Lạt | D33: 420104 | E33: Phường 12 | F33: 22312000 | G33: Bưu Cục Số 6 Trương Văn Hoàn-Phường 9-Đà Lạt-Lâm Đồng | H33: 22312000 | I33: Bưu Cục Số 6 Trương Văn Hoàn-Phường 9-Đà Lạt-Lâm Đồng | J33: TRUE | K33: A | L33: 1 | M33: 16 | N33: 15 | O33: Đã mở
A34: Lâm Đồng | B34: 1550 | C34: Thành phố Đà Lạt | D34: 420105 | E34: Phường 2 | F34: 21687000 | G34: Bưu Cục Cao Bá Quát-Phường 7-Đà Lạt-Lâm Đồng | H34: 21130000 | I34: Kho Giao Hàng Nặng - TP Đà Lạt - Lâm Đồng | J34: TRUE | K34: A | L34: 1 | M34: 15 | N34: 15 | O34: Đã mở
A35: Lâm Đồng | B35: 1550 | C35: Thành phố Đà Lạt | D35: 420106 | E35: Phường 3 | F35: 21126000 | G35: Bưu cục Ngô Thỳ Sỹ - Đà Lạt - Lâm Đồng | H35: 21126000 | I35: Bưu cục Ngô Thỳ Sỹ - Đà Lạt - Lâm Đồng | J35: TRUE | K35: A | L35: 1 | M35: 18 | N35: 15 | O35: Đã mở
A36: Lâm Đồng | B36: 1550 | C36: Thành phố Đà Lạt | D36: 420107 | E36: Phường 4 | F36: 21126000 | G36: Bưu cục Ngô Thỳ Sỹ - Đà Lạt - Lâm Đồng | H36: 21126000 | I36: Bưu cục Ngô Thỳ Sỹ - Đà Lạt - Lâm Đồng | J36: TRUE | K36: A | L36: 1 | M36: 18 | N36: 15 | O36: Đã mở
A37: Lâm Đồng | B37: 1550 | C37: Thành phố Đà Lạt | D37: 420108 | E37: Phường 5 | F37: 21687000 | G37: Bưu Cục Cao Bá Quát-Phường 7-Đà Lạt-Lâm Đồng | H37: 21687000 | I37: Bưu Cục Cao Bá Quát-Phường 7-Đà Lạt-Lâm Đồng | J37: TRUE | K37: A | L37: 1 | M37: 15 | N37: 15 | O37: Đã mở
A38: Lâm Đồng | B38: 1550 | C38: Thành phố Đà Lạt | D38: 420109 | E38: Phường 6 | F38: 21687000 | G38: Bưu Cục Cao Bá Quát-Phường 7-Đà Lạt-Lâm Đồng | H38: 21687000 | I38: Bưu Cục Cao Bá Quát-Phường 7-Đà Lạt-Lâm Đồng | J38: TRUE | K38: A | L38: 1 | M38: 15 | N38: 15 | O38: Đã mở
A39: Lâm Đồng | B39: 1550 | C39: Thành phố Đà Lạt | D39: 420110 | E39: Phường 7 | F39: 22051000 | G39: Bưu Cục Langbiang-Lạc Dương-Lâm Đồng | H39: 22051000 | I39: Bưu Cục Langbiang-Lạc Dương-Lâm Đồng | J39: TRUE | K39: A | L39: 1 | M39: 15 | N39: 15 | O39: Đã mở
A40: Lâm Đồng | B40: 1550 | C40: Thành phố Đà Lạt | D40: 420111 | E40: Phường 8 | F40: 21537000 | G40: Bưu Cục 190/11 Phù Đổng Thiên Vương-Phường 8-Đà Lạt-Lâm Đồng | H40: 21537000 | I40: Bưu Cục 190/11 Phù Đổng Thiên Vương-Phường 8-Đà Lạt-Lâm Đồng | J40: TRUE | K40: A | L40: 1 | M40: 15 | N40: 15 | O40: Đã mở
...

Sheet 3_KQ_BC_Detail
A1: vung | B1: routed_bc_id | C1: routed_bc_name | D1: bc_type | E1: weight_group | F1: T07/2026 | G1: T08/2026 | H1: T09/2026 | I1: T10/2026 | J1: T11/2026 | K1: T12/2026
A2: NTB | B2: 1896 | C2: Bưu Cục Đạ Huoai-Lâm Đồng | D2: thuong | E2: 10-15kg | F2: 539.83243 | G2: 649.49041 | H2: 698.61626 | I2: 802.08077 | J2: 853.60643 | K2: 915.364
A3: NTB | B3: 1896 | C3: Bưu Cục Đạ Huoai-Lâm Đồng | D3: thuong | E3: 15-30kg | F3: 592.45182 | G3: 712.06965 | H3: 766.95038 | I3: 881.95331 | J3: 941.49746 | K3: 1011.56
A4: NTB | B4: 1896 | C4: Bưu Cục Đạ Huoai-Lâm Đồng | D4: thuong | E4: 5-10kg | F4: 755.49504 | G4: 809.85937 | H4: 805.46329 | I4: 861.48822 | J4: 915.14338 | K4: 1005.6558
A5: NTB | B5: 1896 | C5: Bưu Cục Đạ Huoai-Lâm Đồng | D5: thuong | E5: <5kg | F5: 11266.725 | G5: 12190.318 | H5: 12140.779 | I5: 13008.673 | J5: 13997.647 | K5: 15519.416
A6: NTB | B6: 1896 | C6: Bưu Cục Đạ Huoai-Lâm Đồng | D6: thuong | E6: ≥30kg | F6: 207.21288 | G6: 251.73526 | H6: 273.22398 | I6: 316.1142 | J6: 335.9797 | K6: 358.93995
A7: NTB | B7: 2309 | C7: (DNO) Đức Lập | D7: thuong | E7: 10-15kg | F7: 1207.7726 | G7: 1436.1775 | H7: 1529.847 | I7: 1742.5124 | J7: 1866.0517 | K7: 2016.618
A8: NTB | B8: 2309 | C8: (DNO) Đức Lập | D8: thuong | E8: 15-30kg | F8: 1258.6382 | G8: 1539.2931 | H8: 1671.0286 | I8: 1932.603 | J8: 2051.2347 | K8: 2189.1173
A9: NTB | B9: 2309 | C9: (DNO) Đức Lập | D9: thuong | E9: 5-10kg | F9: 1869.0383 | G9: 2032.1069 | H9: 2026.3114 | I9: 2174.0008 | J9: 2350.0695 | K9: 2613.1075
A10: NTB | B10: 2309 | C10: (DNO) Đức Lập | D10: thuong | E10: <5kg | F10: 30771.221 | G10: 33836.39 | H10: 33646.506 | I10: 35980.669 | J10: 39222.909 | K10: 43925.074
A11: NTB | B11: 2309 | C11: (DNO) Đức Lập | D11: thuong | E11: ≥30kg | F11: 480.5356 | G11: 587.36574 | H11: 638.95492 | I11: 740.4017 | J11: 785.49508 | K11: 837.44771
A12: NTB | B12: 2357 | C12: (BTH) Đồng Kho | D12: thuong | E12: 10-15kg | F12: 1068.5014 | G12: 1279.2832 | H12: 1370.7096 | I12: 1568.5265 | J12: 1670.488 | K12: 1794.4607
A13: NTB | B13: 2357 | C13: (BTH) Đồng Kho | D13: thuong | E13: 15-30kg | F13: 1158.6477 | G13: 1409.5557 | H13: 1527.5075 | I13: 1764.582 | J13: 1875.7439 | K13: 2005.1692
... A393: NTB | B393: 23015000 | C393: (LDO) Bảo Lâm 3 | D393: thuong | E393: ≥30kg | F393: 198.88321 | G393: 243.36412 | H393: 265.04399 | I393: 307.41517 | J393: 325.93923 | K393: 347.2106

Sheet 4_KQ_B2B
A1: Vùng | B1: Tỉnh | C1: Quận_ID | D1: Phường_ID | E1: B2B_Nhóm | F1: B2B_Từ_kg | G1: B2B_Pct | H1: B2B_Status | I1: routed_bc_id | J1: routed_bc_name | K1: Weight_Band | L1: T07/2026 | M1: T08/2026 | N1: T09/2026 | O1: T10/2026 | P1: T11/2026 | Q1: T12/2026 | R1: TOTAL_T05_T12
A2: NTB | B2: Bình Thuận | C2: 1666 | D2: 470102 | E2: A | F2: 15 | G2: 1 | H2: Đã mở | J2: GHN B2B Bình Thuận (sắp mở) | K2: 15to30 | L2: 189.09736 | M2: 234.97344 | N2: 257.41895 | O2: 299.7771 | P2: 316.35966 | Q2: 335.21347 | R2: 1632.84
A3: NTB | B3: Bình Thuận | C3: 1666 | D3: 470102 | E3: A | F3: 15 | G3: 1 | H3: Đã mở | J3: GHN B2B Bình Thuận (sắp mở) | K3: gte30 | L3: 59.500775 | M3: 73.44988 | N3: 80.296151 | O3: 93.382449 | P3: 98.734229 | Q3: 104.83534 | R3: 510.19882
A4: NTB | B4: Bình Thuận | C4: 1666 | D4: 470105 | E4: A | F4: 15 | G4: 1 | H4: Đã mở | J4: GHN B2B Bình Thuận (sắp mở) | K4: 15to30 | L4: 443.00062 | M4: 558.40556 | N4: 616.12638 | O4: 721.24646 | P4: 757.49328 | Q4: 797.93015 | R4: 3894.2024
A5: NTB | B5: Bình Thuận | C5: 1666 | D5: 470105 | E5: A | F5: 15 | G5: 1 | H5: Đã mở | J5: GHN B2B Bình Thuận (sắp mở) | K5: gte30 | L5: 186.64278 | M5: 234.93969 | N5: 259.19901 | O5: 303.4308 | P5: 318.79355 | Q5: 335.91244 | R5: 1638.9183
A6: NTB | B6: Bình Thuận | C6: 1666 | D6: 470106 | E6: A | F6: 15 | G6: 1 | H6: Đã mở | J6: GHN B2B Bình Thuận (sắp mở) | K6: 15to30 | L6: 62.983102 | M6: 78.574471 | N6: 86.252071 | O6: 100.59138 | P6: 106.01168 | Q6: 112.14418 | R6: 546.55688
A7: NTB | B7: Bình Thuận | C7: 1666 | D7: 470106 | E7: A | F7: 15 | G7: 1 | H7: Đã mở | J7: GHN B2B Bình Thuận (sắp mở) | K7: gte30 | L7: 25.104995 | M7: 31.758811 | N7: 35.118431 | O7: 41.178338 | P7: 43.195344 | Q7: 45.427954 | R7: 221.78387
A8: NTB | B8: Bình Thuận | C8: 1666 | D8: 470107 | E8: A | F8: 15 | G8: 1 | H8: Đã mở | J8: GHN B2B Bình Thuận (sắp mở) | K8: 15to30 | L8: 227.69683 | M8: 283.93027 | N8: 311.59931 | O8: 363.33746 | P8: 382.95805 | Q8: 405.17453 | R8: 1974.6965
A9: NTB | B9: Bình Thuận | C9: 1666 | D9: 470107 | E9: A | F9: 15 | G9: 1 | H9: Đã mở | J9: GHN B2B Bình Thuận (sắp mở) | K9: gte30 | L9: 77.525141 | M9: 96.134203 | N9: 105.32069 | O9: 122.67561 | P9: 129.5123 | Q9: 137.26845 | R9: 668.43639
A10: NTB | B10: Bình Thuận | C10: 1666 | D10: 470108 | E10: A | F10: 15 | G10: 1 | H10: Đã mở | J10: GHN B2B Bình Thuận (sắp mở) | K10: 15to30 | L10: 500.47454 | M10: 626.26722 | N10: 688.5009 | O10: 803.8413 | P10: 846.20607 | Q10: 893.96913 | R10: 4359.2592
A11: NTB | B11: Bình Thuận | C11: 1666 | D11: 470108 | E11: A | F11: 15 | G11: 1 | H11: Đã mở | J11: GHN B2B Bình Thuận (sắp mở) | K11: gte30 | L11: 199.69562 | M11: 247.40729 | N11: 270.93385 | O11: 315.48174 | P11: 333.16222 | Q11: 353.24034 | R11: 1719.9211
A12: NTB | B12: Bình Thuận | C12: 1666 | D12: 470109 | E12: A | F12: 15 | G12: 1 | H12: Đã mở | J12: GHN B2B Bình Thuận (sắp mở) | K12: 15to30 | L12: 278.546 | M12: 348.40034 | N12: 382.93855 | O12: 447.02385 | P12: 470.70215 | Q12: 497.40146 | R12: 2425.0124
